Workbook
Name ColumnTitle10: ExpOct[[#Headers],[日期]]
Name ColumnTitle10: ExpSep[[#Headers],[日期]]
Name ColumnTitle10: ExpAug[[#Headers],[日期]]
Name ColumnTitle10: ExpAug[[#Headers],[日期]]
Name ColumnTitle11: #REF!
Name ColumnTitle12: #REF!
Name ColumnTitle12: #REF!
Name ColumnTitle12: #REF!
Name ColumnTitle13: ExpNov[[#Headers],[日期]]
Name ColumnTitle13: ExpNov[[#Headers],[日期]]
Name ColumnTitle13: ExpNov[[#Headers],[日期]]
Name ColumnTitle13: ExpNov[[#Headers],[日期]]
Name ColumnTitle14: ExpDec[[#Headers],[日期]]
Name ColumnTitle14: ExpDec[[#Headers],[日期]]
Name ColumnTitle14: ExpDec[[#Headers],[日期]]
Name ColumnTitle14: ExpDec[[#Headers],[日期]]
Name ColumnTitle2: 资产摘要[[#Headers],[资产归属]]
Name ColumnTitle2: 资产摘要[[#Headers],[资产归属]]
Name ColumnTitle2: 投资收益表[[#Headers],[投资分类]]
Name ColumnTitle2: 资产摘要[[#Headers],[资产归属]]
Name ColumnTitle3: ExpJan[[#Headers],[日期]]
Name ColumnTitle3: ExpJan[[#Headers],[日期]]
Name ColumnTitle3: ExpJan[[#Headers],[日期]]
Name ColumnTitle3: ExpJan[[#Headers],[日期]]
Name ColumnTitle4: ExpFeb[[#Headers],[日期]]
Name ColumnTitle4: ExpFeb[[#Headers],[日期]]
Name ColumnTitle4: ExpFeb[[#Headers],[日期]]
Name ColumnTitle4: ExpFeb[[#Headers],[日期]]
Name ColumnTitle5: ExpMar[[#Headers],[日期]]
Name ColumnTitle5: ExpMar[[#Headers],[日期]]
Name ColumnTitle5: ExpMar[[#Headers],[日期]]
Name ColumnTitle5: ExpMar[[#Headers],[日期]]
Name ColumnTitle6: ExpApr[[#Headers],[日期]]
Name ColumnTitle6: ExpApr[[#Headers],[日期]]
Name ColumnTitle6: ExpApr[[#Headers],[日期]]
Name ColumnTitle6: ExpApr[[#Headers],[日期]]
Name ColumnTitle7: ExpMay[[#Headers],[日期]]
Name ColumnTitle7: ExpMay[[#Headers],[日期]]
Name ColumnTitle7: ExpMay[[#Headers],[日期]]
Name ColumnTitle7: ExpMay[[#Headers],[日期]]
Name ColumnTitle8: ExpJun[[#Headers],[日期]]
Name ColumnTitle8: ExpJun[[#Headers],[日期]]
Name ColumnTitle8: ExpJun[[#Headers],[日期]]
Name ColumnTitle8: ExpJun[[#Headers],[日期]]
Name ColumnTitle9: ExpJul[[#Headers],[日期]]
Name ColumnTitle9: ExpJul[[#Headers],[日期]]
Name ColumnTitle9: ExpJul[[#Headers],[日期]]
Name ColumnTitle9: ExpJul[[#Headers],[日期]]
Name ExpenseCategories: 资产摘要[资产归属]
Name ExpenseCategories: 资产摘要[资产归属]
Name ExpenseCategories: 投资收益表[投资分类]
Name ExpenseCategories: 资产摘要[资产归属]
Name 类别: #REF!
Name 美股投资组合: #REF!

Sheet 总资产摘要
A1: 资产趋势 | B1: 需将下方日期手动更新
B2: =DATE(2026,1,15) -> 46037 | C2: =DATE(2026,2,15) -> 46068 | D2: =DATE(2026,3,15) -> 46096 | E2: =DATE(2026,4,15) -> 46127 | F2: =DATE(2025,5,15) -> 45792 | G2: =DATE(2025,6,15) -> 45823 | H2: =DATE(2025,7,15) -> 45853 | I2: =DATE(2025,8,15) -> 45884 | J2: =DATE(2025,9,15) -> 45915 | K2: =DATE(2025,10,15) -> 45945 | L2: =DATE(2025,11,14) -> 45975 | M2: =DATE(2025,12,15) -> 46006 | N2: 提示
A4: 资产归属 | B4: 1月 | C4: 2月 | D4: 3月 | E4: 4月 | F4: 5月 | G4: 6月 | H4: 7月 | I4: 8月 | J4: 9月 | K4: 10月 | L4: 11月 | M4: 12月 | N4: 差额小计 | O4: 环比增长 | P4: 趋势 | Q4: 占比 | R4: 意见 | S4: 判定下限 | T4: 判定上限
A5: 东莞农村商业银行 | B5: =SUMIFS(ExpJan[金额],ExpJan[类别],资产摘要[[#This Row],[资产归属]]) -> 46095 | C5: =SUMIFS(ExpFeb[金额],ExpFeb[类别],资产摘要[[#This Row],[资产归属]]) -> 0.01 | D5: =SUMIFS(ExpMar[金额],ExpMar[类别],资产摘要[[#This Row],[资产归属]]) -> 0.01 | E5: =SUMIFS(ExpApr[金额],ExpApr[类别],资产摘要[[#This Row],[资产归属]]) -> 0 | F5: =SUMIFS(ExpMay[金额],ExpMay[类别],资产摘要[[#This Row],[资产归属]]) -> 0 | G5: =SUMIFS(ExpJun[金额],ExpJun[类别],资产摘要[[#This Row],[资产归属]]) -> 81466.09 | H5: =SUMIFS(ExpJul[金额],ExpJul[类别],资产摘要[[#This Row],[资产归属]]) -> 81503.45 | I5: =SUMIFS(ExpAug[金额],ExpAug[类别],资产摘要[[#This Row],[资产归属]]) -> 81591.43 | J5: =SUMIFS(ExpSep[金额],ExpSep[类别],资产摘要[[#This Row],[资产归属]]) -> 77615.66 | K5: =SUMIFS(ExpOct[金额],ExpOct[类别],资产摘要[[#This Row],[资产归属]]) -> 73876.46 | L5: =SUMIFS(ExpNov[金额],ExpNov[类别],资产摘要[[#This Row],[资产归属]]) -> 69682.36 | M5: =SUMIFS(ExpDec[金额],ExpDec[类别],资产摘要[[#This Row],[资产归属]]) -> 56685.01 | N5: {=IFERROR( IF( INDEX(B5:M5, MONTH(TODAY())) = 0, INDEX(B5:M5, IF(MONTH(TODAY())=1, 12, MONTH(TODAY())-1)) - INDEX(B5:M5, IF(MONTH(TODAY())=1, 11, MONTH(TODAY())-2)), INDEX(B5:M5, MONTH(TODAY())) - INDEX(B5:M5, IF(MONTH(TODAY())=1, 12, MONTH(TODAY())-1)) ), "" )} -> -0.01 | O5: {=IFERROR( IF( INDEX(B5:M5, MONTH(TODAY())) = 0, INDEX(B5:M5, IF(MONTH(TODAY())=1, 12, MONTH(TODAY())-1)) - INDEX(B5:M5, IF(MONTH(TODAY())=1, 11, MONTH(TODAY())-2)), INDEX(B5:M5, MONTH(TODAY())) - INDEX(B5:M5, IF(MONTH(TODAY())=1, 12, MONTH(TODAY())-1)) ), "" )/ IFERROR( IF( INDEX(B5:M5, MONTH(TODAY())) = 0, INDEX(B5:M5,MONTH(TODAY())-1), INDEX(B5:M5,MONTH(TODAY())) ), "" )} -> #DIV/0! | Q5: =INDEX(资产摘要[#This Row], MATCH(TEXT(TODAY(),"m") & "月", 资产摘要[#Headers], 0))/INDEX(资产摘要[#Totals], MATCH(TEXT(TODAY(),"m") & "月", 资产摘要[#Headers], 0)) -> 0 | R5: =IF(AND(资产摘要[[#This Row],[占比]]>=资产摘要[[#This Row],[判定下限]], 资产摘要[[#This Row],[占比]]<=资产摘要[[#This Row],[判定上限]]),"合理","不合理") -> 合理 | S5: 0 | T5: 0.05
A6: 招商银行 | B6: =SUMIFS(ExpJan[金额],ExpJan[类别],资产摘要[[#This Row],[资产归属]]) -> 192935.76 | C6: =SUMIFS(ExpFeb[金额],ExpFeb[类别],资产摘要[[#This Row],[资产归属]]) -> 260187.53 | D6: =SUMIFS(ExpMar[金额],ExpMar[类别],资产摘要[[#This Row],[资产归属]]) -> 429074.87 | E6: =SUMIFS(ExpApr[金额],ExpApr[类别],资产摘要[[#This Row],[资产归属]]) -> 353671.01 | F6: =SUMIFS(ExpMay[金额],ExpMay[类别],资产摘要[[#This Row],[资产归属]]) -> 372604.37 | G6: =SUMIFS(ExpJun[金额],ExpJun[类别],资产摘要[[#This Row],[资产归属]]) -> 153397.45 | H6: =SUMIFS(ExpJul[金额],ExpJul[类别],资产摘要[[#This Row],[资产归属]]) -> 162079.94 | I6: =SUMIFS(ExpAug[金额],ExpAug[类别],资产摘要[[#This Row],[资产归属]]) -> 169392.9 | J6: =SUMIFS(ExpSep[金额],ExpSep[类别],资产摘要[[#This Row],[资产归属]]) -> 172458.4 | K6: =SUMIFS(ExpOct[金额],ExpOct[类别],资产摘要[[#This Row],[资产归属]]) -> 168232.73 | L6: =SUMIFS(ExpNov[金额],ExpNov[类别],资产摘要[[#This Row],[资产归属]]) -> 173631.04 | M6: =SUMIFS(ExpDec[金额],ExpDec[类别],资产摘要[[#This Row],[资产归属]]) -> 187595.64 | N6: {=IFERROR( IF( INDEX(B6:M6, MONTH(TODAY())) = 0, INDEX(B6:M6, IF(MONTH(TODAY())=1, 12, MONTH(TODAY())-1)) - INDEX(B6:M6, IF(MONTH(TODAY())=1, 11, MONTH(TODAY())-2)), INDEX(B6:M6, MONTH(TODAY())) - INDEX(B6:M6, IF(MONTH(TODAY())=1, 12, MONTH(TODAY())-1)) ), "" )} -> 18933.36 | O6: {=IFERROR( IF( INDEX(B6:M6, MONTH(TODAY())) = 0, INDEX(B6:M6, IF(MONTH(TODAY())=1, 12, MONTH(TODAY())-1)) - INDEX(B6:M6, IF(MONTH(TODAY())=1, 11, MONTH(TODAY())-2)), INDEX(B6:M6, MONTH(TODAY())) - INDEX(B6:M6, IF(MONTH(TODAY())=1, 12, MONTH(TODAY())-1)) ), "" )/ IFERROR( IF( INDEX(B6:M6, MONTH(TODAY())) = 0, INDEX(B6:M6,MONTH(TODAY())-1), INDEX(B6:M6,MONTH(TODAY())) ), "" )} -> 0.050813575 | Q6: =INDEX(资产摘要[#This Row], MATCH(TEXT(TODAY(),"m") & "月", 资产摘要[#Headers], 0))/INDEX(资产摘要[#Totals], MATCH(TEXT(TODAY(),"m") & "月", 资产摘要[#Headers], 0)) -> 0.65240945 | R6: =IF(AND(资产摘要[[#This Row],[占比]]>=资产摘要[[#This Row],[判定下限]], 资产摘要[[#This Row],[占比]]<=资产摘要[[#This Row],[判定上限]]),"合理","不合理") -> 合理 | S6: 0.6 | T6: 0.8
A7: 中国银行 | B7: =SUMIFS(ExpJan[金额],ExpJan[类别],资产摘要[[#This Row],[资产归属]]) -> 2119.37 | C7: =SUMIFS(ExpFeb[金额],ExpFeb[类别],资产摘要[[#This Row],[资产归属]]) -> 2084.81 | D7: =SUMIFS(ExpMar[金额],ExpMar[类别],资产摘要[[#This Row],[资产归属]]) -> 1973.89 | E7: =SUMIFS(ExpApr[金额],ExpApr[类别],资产摘要[[#This Row],[资产归属]]) -> 53.08 | F7: =SUMIFS(ExpMay[金额],ExpMay[类别],资产摘要[[#This Row],[资产归属]]) -> 52.95 | G7: =SUMIFS(ExpJun[金额],ExpJun[类别],资产摘要[[#This Row],[资产归属]]) -> 10458.89 | H7: =SUMIFS(ExpJul[金额],ExpJul[类别],资产摘要[[#This Row],[资产归属]]) -> 12612.22 | I7: =SUMIFS(ExpAug[金额],ExpAug[类别],资产摘要[[#This Row],[资产归属]]) -> 10057.35 | J7: =SUMIFS(ExpSep[金额],ExpSep[类别],资产摘要[[#This Row],[资产归属]]) -> 294.56 | K7: =SUMIFS(ExpOct[金额],ExpOct[类别],资产摘要[[#This Row],[资产归属]]) -> 6.86 | L7: =SUMIFS(ExpNov[金额],ExpNov[类别],资产摘要[[#This Row],[资产归属]]) -> 0.32 | M7: =SUMIFS(ExpDec[金额],ExpDec[类别],资产摘要[[#This Row],[资产归属]]) -> 468.18 | N7: {=IFERROR( IF( INDEX(B7:M7, MONTH(TODAY())) = 0, INDEX(B7:M7, IF(MONTH(TODAY())=1, 12, MONTH(TODAY())-1)) - INDEX(B7:M7, IF(MONTH(TODAY())=1, 11, MONTH(TODAY())-2)), INDEX(B7:M7, MONTH(TODAY())) - INDEX(B7:M7, IF(MONTH(TODAY())=1, 12, MONTH(TODAY())-1)) ), "" )} -> -0.13 | O7: {=IFERROR( IF( INDEX(B7:M7, MONTH(TODAY())) = 0, INDEX(B7:M7, IF(MONTH(TODAY())=1, 12, MONTH(TODAY())-1)) - INDEX(B7:M7, IF(MONTH(TODAY())=1, 11, MONTH(TODAY())-2)), INDEX(B7:M7, MONTH(TODAY())) - INDEX(B7:M7, IF(MONTH(TODAY())=1, 12, MONTH(TODAY())-1)) ), "" )/ IFERROR( IF( INDEX(B7:M7, MONTH(TODAY())) = 0, INDEX(B7:M7,MONTH(TODAY())-1), INDEX(B7:M7,MONTH(TODAY())) ), "" )} -> -0.0024551464 | Q7: =INDEX(资产摘要[#This Row], MATCH(TEXT(TODAY(),"m") & "月", 资产摘要[#Headers], 0))/INDEX(资产摘要[#Totals], MATCH(TEXT(TODAY(),"m") & "月", 资产摘要[#Headers], 0)) -> 9.2712493e-05 | R7: =IF(AND(资产摘要[[#This Row],[占比]]>=资产摘要[[#This Row],[判定下限]], 资产摘要[[#This Row],[占比]]<=资产摘要[[#This Row],[判定上限]]),"合理","不合理") -> 合理 | S7: 0 | T7: 0.5
A8: 中银香港 | B8: =SUMIFS(ExpJan[金额],ExpJan[类别],资产摘要[[#This Row],[资产归属]]) -> 0.009167 | C8: =SUMIFS(ExpFeb[金额],ExpFeb[类别],资产摘要[[#This Row],[资产归属]]) -> 0.009167 | D8: =SUMIFS(ExpMar[金额],ExpMar[类别],资产摘要[[#This Row],[资产归属]]) -> 0.009167 | E8: =SUMIFS(ExpApr[金额],ExpApr[类别],资产摘要[[#This Row],[资产归属]]) -> 0.009167 | F8: =SUMIFS(ExpMay[金额],ExpMay[类别],资产摘要[[#This Row],[资产归属]]) -> 0.009167 | G8: =SUMIFS(ExpJun[金额],ExpJun[类别],资产摘要[[#This Row],[资产归属]]) -> 5701.12 | H8: =SUMIFS(ExpJul[金额],ExpJul[类别],资产摘要[[#This Row],[资产归属]]) -> 0.071264 | I8: =SUMIFS(ExpAug[金额],ExpAug[类别],资产摘要[[#This Row],[资产归属]]) -> 0.009167 | J8: =SUMIFS(ExpSep[金额],ExpSep[类别],资产摘要[[#This Row],[资产归属]]) -> 0.09167 | K8: =SUMIFS(ExpOct[金额],ExpOct[类别],资产摘要[[#This Row],[资产归属]]) -> 0 | L8: =SUMIFS(ExpNov[金额],ExpNov[类别],资产摘要[[#This Row],[资产归属]]) -> 0.009167 | M8: =SUMIFS(ExpDec[金额],ExpDec[类别],资产摘要[[#This Row],[资产归属]]) -> 0.009167 | N8: {=IFERROR( IF( INDEX(B8:M8, MONTH(TODAY())) = 0, INDEX(B8:M8, IF(MONTH(TODAY())=1, 12, MONTH(TODAY())-1)) - INDEX(B8:M8, IF(MONTH(TODAY())=1, 11, MONTH(TODAY())-2)), INDEX(B8:M8, MONTH(TODAY())) - INDEX(B8:M8, IF(MONTH(TODAY())=1, 12, MONTH(TODAY())-1)) ), "" )} -> 0 | O8: {=IFERROR( IF( INDEX(B8:M8, MONTH(TODAY())) = 0, INDEX(B8:M8, IF(MONTH(TODAY())=1, 12, MONTH(TODAY())-1)) - INDEX(B8:M8, IF(MONTH(TODAY())=1, 11, MONTH(TODAY())-2)), INDEX(B8:M8, MONTH(TODAY())) - INDEX(B8:M8, IF(MONTH(TODAY())=1, 12, MONTH(TODAY())-1)) ), "" )/ IFERROR( IF( INDEX(B8:M8, MONTH(TODAY())) = 0, INDEX(B8:M8,MONTH(TODAY())-1), INDEX(B8:M8,MONTH(TODAY())) ), "" )} -> 0 | Q8: =INDEX(资产摘要[#This Row], MATCH(TEXT(TODAY(),"m") & "月", 资产摘要[#Headers], 0))/INDEX(资产摘要[#Totals], MATCH(TEXT(TODAY(),"m") & "月", 资产摘要[#Headers], 0)) -> 1.6050905e-08 | R8: =IF(AND(资产摘要[[#This Row],[占比]]>=资产摘要[[#This Row],[判定下限]], 资产摘要[[#This Row],[占比]]<=资产摘要[[#This Row],[判定上限]]),"合理","不合理") -> 合理 | S8: 0 | T8: 0.05
A9: 支付宝 | B9: =SUMIFS(ExpJan[金额],ExpJan[类别],资产摘要[[#This Row],[资产归属]]) -> 0.2 | C9: =SUMIFS(ExpFeb[金额],ExpFeb[类别],资产摘要[[#This Row],[资产归属]]) -> 10086.78 | D9: =SUMIFS(ExpMar[金额],ExpMar[类别],资产摘要[[#This Row],[资产归属]]) -> 0.02 | E9: =SUMIFS(ExpApr[金额],ExpApr[类别],资产摘要[[#This Row],[资产归属]]) -> 0.04 | F9: =SUMIFS(ExpMay[金额],ExpMay[类别],资产摘要[[#This Row],[资产归属]]) -> 1.04 | G9: =SUMIFS(ExpJun[金额],ExpJun[类别],资产摘要[[#This Row],[资产归属]]) -> 310.98 | H9: =SUMIFS(ExpJul[金额],ExpJul[类别],资产摘要[[#This Row],[资产归属]]) -> 46.54 | I9: =SUMIFS(ExpAug[金额],ExpAug[类别],资产摘要[[#This Row],[资产归属]]) -> 1.96 | J9: =SUMIFS(ExpSep[金额],ExpSep[类别],资产摘要[[#This Row],[资产归属]]) -> 0.96 | K9: =SUMIFS(ExpOct[金额],ExpOct[类别],资产摘要[[#This Row],[资产归属]]) -> 1.15 | L9: =SUMIFS(ExpNov[金额],ExpNov[类别],资产摘要[[#This Row],[资产归属]]) -> 0.15 | M9: =SUMIFS(ExpDec[金额],ExpDec[类别],资产摘要[[#This Row],[资产归属]]) -> 63.5 | N9: {=IFERROR( IF( INDEX(B9:M9, MONTH(TODAY())) = 0, INDEX(B9:M9, IF(MONTH(TODAY())=1, 12, MONTH(TODAY())-1)) - INDEX(B9:M9, IF(MONTH(TODAY())=1, 11, MONTH(TODAY())-2)), INDEX(B9:M9, MONTH(TODAY())) - INDEX(B9:M9, IF(MONTH(TODAY())=1, 12, MONTH(TODAY())-1)) ), "" )} -> 1 | O9: {=IFERROR( IF( INDEX(B9:M9, MONTH(TODAY())) = 0, INDEX(B9:M9, IF(MONTH(TODAY())=1, 12, MONTH(TODAY())-1)) - INDEX(B9:M9, IF(MONTH(TODAY())=1, 11, MONTH(TODAY())-2)), INDEX(B9:M9, MONTH(TODAY())) - INDEX(B9:M9, IF(MONTH(TODAY())=1, 12, MONTH(TODAY())-1)) ), "" )/ IFERROR( IF( INDEX(B9:M9, MONTH(TODAY())) = 0, INDEX(B9:M9,MONTH(TODAY())-1), INDEX(B9:M9,MONTH(TODAY())) ), "" )} -> 0.96153846 | Q9: =INDEX(资产摘要[#This Row], MATCH(TEXT(TODAY(),"m") & "月", 资产摘要[#Headers], 0))/INDEX(资产摘要[#Totals], MATCH(TEXT(TODAY(),"m") & "月", 资产摘要[#Headers], 0)) -> 1.8209819e-06 | R9: =IF(AND(资产摘要[[#This Row],[占比]]>=资产摘要[[#This Row],[判定下限]], 资产摘要[[#This Row],[占比]]<=资产摘要[[#This Row],[判定上限]]),"合理","不合理") -> 合理 | S9: 0 | T9: 0.05
A10: 微信 | B10: =SUMIFS(ExpJan[金额],ExpJan[类别],资产摘要[[#This Row],[资产归属]]) -> 134.86 | C10: =SUMIFS(ExpFeb[金额],ExpFeb[类别],资产摘要[[#This Row],[资产归属]]) -> 866.21 | D10: =SUMIFS(ExpMar[金额],ExpMar[类别],资产摘要[[#This Row],[资产归属]]) -> 7.34 | E10: =SUMIFS(ExpApr[金额],ExpApr[类别],资产摘要[[#This Row],[资产归属]]) -> 1.9 | F10: =SUMIFS(ExpMay[金额],ExpMay[类别],资产摘要[[#This Row],[资产归属]]) -> 9.9 | G10: =SUMIFS(ExpJun[金额],ExpJun[类别],资产摘要[[#This Row],[资产归属]]) -> 1286.09 | H10: =SUMIFS(ExpJul[金额],ExpJul[类别],资产摘要[[#This Row],[资产归属]]) -> 2.93 | I10: =SUMIFS(ExpAug[金额],ExpAug[类别],资产摘要[[#This Row],[资产归属]]) -> 5.95 | J10: =SUMIFS(ExpSep[金额],ExpSep[类别],资产摘要[[#This Row],[资产归属]]) -> 2 | K10: =SUMIFS(ExpOct[金额],ExpOct[类别],资产摘要[[#This Row],[资产归属]]) -> 160.93 | L10: =SUMIFS(ExpNov[金额],ExpNov[类别],资产摘要[[#This Row],[资产归属]]) -> 0.9 | M10: =SUMIFS(ExpDec[金额],ExpDec[类别],资产摘要[[#This Row],[资产归属]]) -> 1.06 | N10: {=IFERROR( INDEX(B10:M10, MONTH(TODAY())) - INDEX(B10:M10, IF(MONTH(TODAY())=1, 12, MONTH(TODAY())-1)), "")} -> 8 | O10: {=IFERROR( IF( INDEX(B10:M10, MONTH(TODAY())) = 0, INDEX(B10:M10, IF(MONTH(TODAY())=1, 12, MONTH(TODAY())-1)) - INDEX(B10:M10, IF(MONTH(TODAY())=1, 11, MONTH(TODAY())-2)), INDEX(B10:M10, MONTH(TODAY())) - INDEX(B10:M10, IF(MONTH(TODAY())=1, 12, MONTH(TODAY())-1)) ), "" )/ IFERROR( IF( INDEX(B10:M10, MONTH(TODAY())) = 0, INDEX(B10:M10,MONTH(TODAY())-1), INDEX(B10:M10,MONTH(TODAY())) ), "" )} -> 0.80808081 | Q10: =INDEX(资产摘要[#This Row], MATCH(TEXT(TODAY(),"m") & "月", 资产摘要[#Headers], 0))/INDEX(资产摘要[#Totals], MATCH(TEXT(TODAY(),"m") & "月", 资产摘要[#Headers], 0)) -> 1.7334347e-05 | R10: =IF(AND(资产摘要[[#This Row],[占比]]>=资产摘要[[#This Row],[判定下限]], 资产摘要[[#This Row],[占比]]<=资产摘要[[#This Row],[判定上限]]),"合理","不合理") -> 合理 | S10: 0 | T10: 0.05
A11: 东方财富 | B11: =SUMIFS(ExpJan[金额],ExpJan[类别],资产摘要[[#This Row],[资产归属]]) -> 41299.21 | C11: =SUMIFS(ExpFeb[金额],ExpFeb[类别],资产摘要[[#This Row],[资产归属]]) -> 42623.14 | D11: =SUMIFS(ExpMar[金额],ExpMar[类别],资产摘要[[#This Row],[资产归属]]) -> 54889.23 | E11: =SUMIFS(ExpApr[金额],ExpApr[类别],资产摘要[[#This Row],[资产归属]]) -> 140024.49 | F11: =SUMIFS(ExpMay[金额],ExpMay[类别],资产摘要[[#This Row],[资产归属]]) -> 140296.64 | G11: =SUMIFS(ExpJun[金额],ExpJun[类别],资产摘要[[#This Row],[资产归属]]) -> 21009.23 | H11: =SUMIFS(ExpJul[金额],ExpJul[类别],资产摘要[[#This Row],[资产归属]]) -> 20932.77 | I11: =SUMIFS(ExpAug[金额],ExpAug[类别],资产摘要[[#This Row],[资产归属]]) -> 21072.81 | J11: =SUMIFS(ExpSep[金额],ExpSep[类别],资产摘要[[#This Row],[资产归属]]) -> 20901.54 | K11: =SUMIFS(ExpOct[金额],ExpOct[类别],资产摘要[[#This Row],[资产归属]]) -> 21785.1 | L11: =SUMIFS(ExpNov[金额],ExpNov[类别],资产摘要[[#This Row],[资产归属]]) -> 22484.1 | M11: =SUMIFS(ExpDec[金额],ExpDec[类别],资产摘要[[#This Row],[资产归属]]) -> 26416.7 | N11: {=IFERROR( IF( INDEX(B11:M11, MONTH(TODAY())) = 0, INDEX(B11:M11, IF(MONTH(TODAY())=1, 12, MONTH(TODAY())-1)) - INDEX(B11:M11, IF(MONTH(TODAY())=1, 11, MONTH(TODAY())-2)), INDEX(B11:M11, MONTH(TODAY())) - INDEX(B11:M11, IF(MONTH(TODAY())=1, 12, MONTH(TODAY())-1)) ), "" )} -> 272.15 | O11: {=IFERROR( IF( INDEX(B11:M11, MONTH(TODAY())) = 0, INDEX(B11:M11, IF(MONTH(TODAY())=1, 12, MONTH(TODAY())-1)) - INDEX(B11:M11, IF(MONTH(TODAY())=1, 11, MONTH(TODAY())-2)), INDEX(B11:M11, MONTH(TODAY())) - INDEX(B11:M11, IF(MONTH(TODAY())=1, 12, MONTH(TODAY())-1)) ), "" )/ IFERROR( IF( INDEX(B11:M11, MONTH(TODAY())) = 0, INDEX(B11:M11,MONTH(TODAY())-1), INDEX(B11:M11,MONTH(TODAY())) ), "" )} -> 0.0019398184 | Q11: =INDEX(资产摘要[#This Row], MATCH(TEXT(TODAY(),"m") & "月", 资产摘要[#Headers], 0))/INDEX(资产摘要[#Totals], MATCH(TEXT(TODAY(),"m") & "月", 资产摘要[#Headers], 0)) -> 0.24565158 | R11: =IF(AND(资产摘要[[#This Row],[占比]]>=资产摘要[[#This Row],[判定下限]], 资产摘要[[#This Row],[占比]]<=资产摘要[[#This Row],[判定上限]]),"合理","不合理") -> 不合理 | S11: 0 | T11: 0.07
A12: 长桥证券 | B12: =SUMIFS(ExpJan[金额],ExpJan[类别],资产摘要[[#This Row],[资产归属]]) -> 46588.66 | C12: =SUMIFS(ExpFeb[金额],ExpFeb[类别],资产摘要[[#This Row],[资产归属]]) -> 48786.92 | D12: =SUMIFS(ExpMar[金额],ExpMar[类别],资产摘要[[#This Row],[资产归属]]) -> 48266.09 | E12: =SUMIFS(ExpApr[金额],ExpApr[类别],资产摘要[[#This Row],[资产归属]]) -> 48651.67 | F12: =SUMIFS(ExpMay[金额],ExpMay[类别],资产摘要[[#This Row],[资产归属]]) -> 49834.35 | G12: =SUMIFS(ExpJun[金额],ExpJun[类别],资产摘要[[#This Row],[资产归属]]) -> 8484.92 | H12: =SUMIFS(ExpJul[金额],ExpJul[类别],资产摘要[[#This Row],[资产归属]]) -> 14584.32 | I12: =SUMIFS(ExpAug[金额],ExpAug[类别],资产摘要[[#This Row],[资产归属]]) -> 14975.57 | J12: =SUMIFS(ExpSep[金额],ExpSep[类别],资产摘要[[#This Row],[资产归属]]) -> 22866.26 | K12: =SUMIFS(ExpOct[金额],ExpOct[类别],资产摘要[[#This Row],[资产归属]]) -> 43401.35 | L12: =SUMIFS(ExpNov[金额],ExpNov[类别],资产摘要[[#This Row],[资产归属]]) -> 46395.65 | M12: =SUMIFS(ExpDec[金额],ExpDec[类别],资产摘要[[#This Row],[资产归属]]) -> 45130.43 | N12: {=IFERROR( IF( INDEX(B12:M12, MONTH(TODAY())) = 0, INDEX(B12:M12, IF(MONTH(TODAY())=1, 12, MONTH(TODAY())-1)) - INDEX(B12:M12, IF(MONTH(TODAY())=1, 11, MONTH(TODAY())-2)), INDEX(B12:M12, MONTH(TODAY())) - INDEX(B12:M12, IF(MONTH(TODAY())=1, 12, MONTH(TODAY())-1)) ), "" )} -> 1182.68 | O12: {=IFERROR( IF( INDEX(B12:M12, MONTH(TODAY())) = 0, INDEX(B12:M12, IF(MONTH(TODAY())=1, 12, MONTH(TODAY())-1)) - INDEX(B12:M12, IF(MONTH(TODAY())=1, 11, MONTH(TODAY())-2)), INDEX(B12:M12, MONTH(TODAY())) - INDEX(B12:M12, IF(MONTH(TODAY())=1, 12, MONTH(TODAY())-1)) ), "" )/ IFERROR( IF( INDEX(B12:M12, MONTH(TODAY())) = 0, INDEX(B12:M12,MONTH(TODAY())-1), INDEX(B12:M12,MONTH(TODAY())) ), "" )} -> 0.023732225 | Q12: =INDEX(资产摘要[#This Row], MATCH(TEXT(TODAY(),"m") & "月", 资产摘要[#Headers], 0))/INDEX(资产摘要[#Totals], MATCH(TEXT(TODAY(),"m") & "月", 资产摘要[#Headers], 0)) -> 0.087257164 | R12: =IF(AND(资产摘要[[#This Row],[占比]]>=资产摘要[[#This Row],[判定下限]], 资产摘要[[#This Row],[占比]]<=资产摘要[[#This Row],[判定上限]]),"合理","不合理") -> 合理 | S12: 0 | T12: 0.1
A13: 币安Biance | B13: =SUMIFS(ExpJan[金额],ExpJan[类别],资产摘要[[#This Row],[资产归属]]) -> 8846.0794 | C13: =SUMIFS(ExpFeb[金额],ExpFeb[类别],资产摘要[[#This Row],[资产归属]]) -> 7530.4296 | D13: =SUMIFS(ExpMar[金额],ExpMar[类别],资产摘要[[#This Row],[资产归属]]) -> 7845.43 | E13: =SUMIFS(ExpApr[金额],ExpApr[类别],资产摘要[[#This Row],[资产归属]]) -> 7988.15 | F13: =SUMIFS(ExpMay[金额],ExpMay[类别],资产摘要[[#This Row],[资产归属]]) -> 8321.18 | G13: =SUMIFS(ExpJun[金额],ExpJun[类别],资产摘要[[#This Row],[资产归属]]) -> 9117.523 | H13: =SUMIFS(ExpJul[金额],ExpJul[类别],资产摘要[[#This Row],[资产归属]]) -> 9103.7375 | I13: =SUMIFS(ExpAug[金额],ExpAug[类别],资产摘要[[#This Row],[资产归属]]) -> 9129.9894 | J13: =SUMIFS(ExpSep[金额],ExpSep[类别],资产摘要[[#This Row],[资产归属]]) -> 8962.8624 | K13: =SUMIFS(ExpOct[金额],ExpOct[类别],资产摘要[[#This Row],[资产归属]]) -> 8791.1158 | L13: =SUMIFS(ExpNov[金额],ExpNov[类别],资产摘要[[#This Row],[资产归属]]) -> 8960.1876 | M13: =SUMIFS(ExpDec[金额],ExpDec[类别],资产摘要[[#This Row],[资产归属]]) -> 8644.3212 | N13: {=IFERROR( IF( INDEX(B13:M13, MONTH(TODAY())) = 0, INDEX(B13:M13, IF(MONTH(TODAY())=1, 12, MONTH(TODAY())-1)) - INDEX(B13:M13, IF(MONTH(TODAY())=1, 11, MONTH(TODAY())-2)), INDEX(B13:M13, MONTH(TODAY())) - INDEX(B13:M13, IF(MONTH(TODAY())=1, 12, MONTH(TODAY())-1)) ), "" )} -> 333.03 | O13: {=IFERROR( IF( INDEX(B13:M13, MONTH(TODAY())) = 0, INDEX(B13:M13, IF(MONTH(TODAY())=1, 12, MONTH(TODAY())-1)) - INDEX(B13:M13, IF(MONTH(TODAY())=1, 11, MONTH(TODAY())-2)), INDEX(B13:M13, MONTH(TODAY())) - INDEX(B13:M13, IF(MONTH(TODAY())=1, 12, MONTH(TODAY())-1)) ), "" )/ IFERROR( IF( INDEX(B13:M13, MONTH(TODAY())) = 0, INDEX(B13:M13,MONTH(TODAY())-1), INDEX(B13:M13,MONTH(TODAY())) ), "" )} -> 0.040021968 | Q13: =INDEX(资产摘要[#This Row], MATCH(TEXT(TODAY(),"m") & "月", 资产摘要[#Headers], 0))/INDEX(资产摘要[#Totals], MATCH(TEXT(TODAY(),"m") & "月", 资产摘要[#Headers], 0)) -> 0.014569922 | R13: =IF(AND(资产摘要[[#This Row],[占比]]>=资产摘要[[#This Row],[判定下限]], 资产摘要[[#This Row],[占比]]<=资产摘要[[#This Row],[判定上限]]),"合理","不合理") -> 不合理 | S13: 0.02 | T13: 0.04
A14: {=IFERROR( _xlfn.LET( _xlpm.data, B14:M14, _xlpm.nonZeroData, IF(_xlpm.data>0, _xlpm.data, ""), _xlpm.minVal, MIN(_xlpm.nonZeroData), _xlpm.maxVal, MAX(_xlpm.data), _xlpm.startPos, MATCH(_xlpm.minVal, _xlpm.nonZeroData, 0), _xlpm.endPos, MATCH(_xlpm.maxVal, _xlpm.data, 0), _xlpm.startDate, INDEX(B2:M2, _xlpm.startPos), _xlpm.endDate, INDEX(B2:M2, _xlpm.endPos), IF(_xlpm.endDate < _xlpm.startDate, "", (_xlpm.maxVal / _xlpm.minVal) -1 ) ), "" )} | B14: =SUBTOTAL(109,资产摘要[1月]) -> 338019.15 | C14: =SUBTOTAL(109,资产摘要[2月]) -> 372165.84 | D14: =SUBTOTAL(109,资产摘要[3月]) -> 542056.89 | E14: =SUBTOTAL(109,资产摘要[4月]) -> 550390.35 | F14: =SUBTOTAL(109,资产摘要[5月]) -> 571120.44 | G14: =SUBTOTAL(109,资产摘要[6月]) -> 291232.29 | H14: =SUBTOTAL(109,资产摘要[7月]) -> 300865.98 | I14: =SUBTOTAL(109,资产摘要[8月]) -> 306227.97 | J14: =SUBTOTAL(109,资产摘要[9月]) -> 303102.33 | K14: =SUBTOTAL(109,资产摘要[10月]) -> 316255.7 | L14: =SUBTOTAL(109,资产摘要[11月]) -> 321154.72 | M14: =SUBTOTAL(109,资产摘要[12月]) -> 325004.85 | N14: =SUBTOTAL(109,资产摘要[差额小计]) -> 20730.08 | O14: {=IFERROR( IF( INDEX(B14:M14, MONTH(TODAY())) = 0, INDEX(B14:M14, IF(MONTH(TODAY())=1, 12, MONTH(TODAY())-1)) - INDEX(B14:M14, IF(MONTH(TODAY())=1, 11, MONTH(TODAY())-2)), INDEX(B14:M14, MONTH(TODAY())) - INDEX(B14:M14, IF(MONTH(TODAY())=1, 12, MONTH(TODAY())-1)) ), "" )/ IFERROR( IF( INDEX(B14:M14, MONTH(TODAY())) = 0, INDEX(B14:M14,MONTH(TODAY())-1), INDEX(B14:M14,MONTH(TODAY())) ), "" )} -> 0.03629723 | P14: {=IFERROR( _xlfn.LET( _xlpm.data, B14:M14, _xlpm.nonZeroData, IF(_xlpm.data>0, _xlpm.data, ""), _xlpm.minVal, MIN(_xlpm.nonZeroData), _xlpm.maxVal, MAX(_xlpm.data), _xlpm.startPos, MATCH(_xlpm.minVal, _xlpm.nonZeroData, 0), _xlpm.endPos, MATCH(_xlpm.maxVal, _xlpm.data, 0), _xlpm.startDate, INDEX(B2:M2, _xlpm.startPos), _xlpm.endDate, INDEX(B2:M2, _xlpm.endPos), IF(_xlpm.endDate < _xlpm.startDate, "", _xlfn.LET( _xlpm.months, DATEDIF(_xlpm.startDate, _xlpm.endDate, "m") +1, (_xlpm.maxVal / _xlpm.minVal) ^ (12/_xlpm.months) -1 ) ) ), "" )} | Q14: =SUBTOTAL(109,资产摘要[占比]) -> 1 | S14: =SUBTOTAL(109,资产摘要[判定下限]) -> 0.62 | T14: =SUBTOTAL(109,资产摘要[判定上限]) -> 1.71
A15: 环比增长C | B15: =资产摘要[[#Totals],[1月]]/资产摘要[[#Totals],[12月]]-1 -> 0.040043397 | C15: =IFERROR( _xlfn.LET( _xlpm.result, 资产摘要[[#Totals],[2月]]/资产摘要[[#Totals],[1月]]-1, IF(OR(_xlpm.result=0, _xlpm.result=-1), 0, _xlpm.result) ), 0 ) -> 0.10101999 | D15: =IFERROR( _xlfn.LET( _xlpm.result, 资产摘要[[#Totals],[3月]]/资产摘要[[#Totals],[2月]]-1, IF(OR(_xlpm.result=0, _xlpm.result=-1), 0, _xlpm.result) ), 0 ) -> 0.45649287 | E15: =IFERROR( _xlfn.LET( _xlpm.result, 资产摘要[[#Totals],[4月]]/资产摘要[[#Totals],[3月]]-1, IF(OR(_xlpm.result=0, _xlpm.result=-1), 0, _xlpm.result) ), 0 ) -> 0.015373774 | F15: =IFERROR( _xlfn.LET( _xlpm.result, 资产摘要[[#Totals],[5月]]/资产摘要[[#Totals],[4月]]-1, IF(OR(_xlpm.result=0, _xlpm.result=-1), 0, _xlpm.result) ), 0 ) -> 0.037664341 | G15: =IFERROR( _xlfn.LET( _xlpm.result, 资产摘要[[#Totals],[6月]]/资产摘要[[#Totals],[5月]]-1, IF(OR(_xlpm.result=0, _xlpm.result=-1), 0, _xlpm.result) ), 0 ) -> -0.49006852 | H15: =IFERROR( _xlfn.LET( _xlpm.result, 资产摘要[[#Totals],[7月]]/资产摘要[[#Totals],[6月]]-1, IF(OR(_xlpm.result=0, _xlpm.result=-1), 0, _xlpm.result) ), 0 ) -> 0.033079044 | I15: =IFERROR( _xlfn.LET( _xlpm.result, 资产摘要[[#Totals],[8月]]/资产摘要[[#Totals],[7月]]-1, IF(OR(_xlpm.result=0, _xlpm.result=-1), 0, _xlpm.result) ), 0 ) -> 0.017821855 | J15: =IFERROR( _xlfn.LET( _xlpm.result, 资产摘要[[#Totals],[9月]]/资产摘要[[#Totals],[8月]]-1, IF(OR(_xlpm.result=0, _xlpm.result=-1), 0, _xlpm.result) ), 0 ) -> -0.010206888 | K15: =IFERROR( _xlfn.LET( _xlpm.result, 资产摘要[[#Totals],[10月]]/资产摘要[[#Totals],[9月]]-1, IF(OR(_xlpm.result=0, _xlpm.result=-1), 0, _xlpm.result) ), 0 ) -> 0.043395778 | L15: =IFERROR( _xlfn.LET( _xlpm.result, 资产摘要[[#Totals],[11月]]/资产摘要[[#Totals],[10月]]-1, IF(OR(_xlpm.result=0, _xlpm.result=-1), 0, _xlpm.result) ), 0 ) -> 0.015490696 | M15: =IFERROR( _xlfn.LET( _xlpm.result, 资产摘要[[#Totals],[12月]]/资产摘要[[#Totals],[11月]]-1, IF(OR(_xlpm.result=0, _xlpm.result=-1), 0, _xlpm.result) ), 0 ) -> 0.011988407 | N15: =IF(COUNTIF(B15:M15, ">-10%")>0, SUMIF(B15:M15, ">-10%")/COUNTIF(B15:M15, ">-10%"), 0) -> 0.069287569
U17: 预测年份 | V17: 预测年末资产（元）
U18: =YEAR(TODAY()) -> 2026 | V18: =MAX(资产摘要[[#Totals],[1月]:[12月]])* (1+$N$15)^( (U18 - YEAR(TODAY())) * 12 + (12 - MONTH(TODAY())) ) -> 912828.79
U19: =U18+1 -> 2027 | V19: =MAX(资产摘要[[#Totals],[1月]:[12月]])* (1+$N$15)^( (U19 - YEAR(TODAY())) * 12 + (12 - MONTH(TODAY())) ) -> 2039499.2
U20: =U19+1 -> 2028 | V20: =MAX(资产摘要[[#Totals],[1月]:[12月]])* (1+$N$15)^( (U20 - YEAR(TODAY())) * 12 + (12 - MONTH(TODAY())) ) -> 4556776.8
U21: =U20+1 -> 2029 | V21: =MAX(资产摘要[[#Totals],[1月]:[12月]])* (1+$N$15)^( (U21 - YEAR(TODAY())) * 12 + (12 - MONTH(TODAY())) ) -> 10181036
U22: =U21+1 -> 2030 | V22: =MAX(资产摘要[[#Totals],[1月]:[12月]])* (1+$N$15)^( (U22 - YEAR(TODAY())) * 12 + (12 - MONTH(TODAY())) ) -> 22747108

Sheet 投资收益表
A1: 投资收益率趋势 | B1: 需将下方日期手动更新
B2: =DATE(2026,1,30) -> 46052 | C2: =DATE(2026,2,28) -> 46081 | D2: =DATE(2026,3,30) -> 46111 | E2: =DATE(2026,4,30) -> 46142 | F2: =总资产摘要!F2 -> 45792 | G2: =总资产摘要!G2 -> 45823 | H2: =总资产摘要!H2 -> 45853 | I2: =总资产摘要!I2 -> 45884 | J2: =总资产摘要!J2 -> 45915 | K2: =总资产摘要!K2 -> 45945 | L2: =总资产摘要!L2 -> 45975 | M2: =总资产摘要!M2 -> 46006 | N2: 提示
A4: 投资分类 | B4: 1月 | C4: 2月 | D4: 3月 | E4: 4月 | F4: 5月 | G4: 6月 | H4: 7月 | I4: 8月 | J4: 9月 | K4: 10月 | L4: 11月 | M4: 12月 | N4: 全年统计 | O4: 环比增长 | P4: 趋势 | Q4: 占比 | R4: 意见 | S4: 判定下限 | T4: 判定上限
A5: 东方财富（A股） | B5: =SUMIFS(ExpJan投资组合[金额],ExpJan投资组合[分类],投资收益表[[#This Row],[投资分类]]) -> 1789.74 | C5: =SUMIFS(ExpFeb投资组合[金额],ExpFeb投资组合[分类],投资收益表[[#This Row],[投资分类]]) -> 682.66 | D5: =SUMIFS(ExpMar投资组合[金额],ExpMar投资组合[分类],投资收益表[[#This Row],[投资分类]]) -> -558.57 | E5: =SUMIFS(ExpApr投资组合[金额],ExpApr投资组合[分类],投资收益表[[#This Row],[投资分类]]) -> 1059.07 | F5: =SUMIFS(ExpMay投资组合[金额],ExpMay投资组合[分类],投资收益表[[#This Row],[投资分类]]) -> 388.65 | G5: =SUMIFS(ExpJun投资组合[金额],ExpJun投资组合[分类],投资收益表[[#This Row],[投资分类]]) -> 626.84 | H5: =SUMIFS(ExpJul投资组合[金额],ExpJul投资组合[分类],投资收益表[[#This Row],[投资分类]]) -> 172.98 | I5: =SUMIFS(ExpAug投资组合[金额],ExpAug投资组合[分类],投资收益表[[#This Row],[投资分类]]) -> -59.03 | J5: =SUMIFS(ExpSep投资组合[金额],ExpSep投资组合[分类],投资收益表[[#This Row],[投资分类]]) -> -167.04 | K5: =SUMIFS(ExpOct投资组合[金额],ExpOct投资组合[分类],投资收益表[[#This Row],[投资分类]]) -> 1083.94 | L5: =SUMIFS(ExpNov投资组合[金额],ExpNov投资组合[分类],投资收益表[[#This Row],[投资分类]]) -> -841 | M5: =SUMIFS(ExpDec投资组合[金额],ExpDec投资组合[分类],投资收益表[[#This Row],[投资分类]]) -> 9.07 | N5: =SUBTOTAL(9,投资收益表[[#This Row],[1月]:[12月]]) -> 4187.31 | O5: {=IFERROR( IF( INDEX(B5:M5, MONTH(TODAY())) = 0, INDEX(B5:M5, IF(MONTH(TODAY())=1, 12, MONTH(TODAY())-1)) - INDEX(B5:M5, IF(MONTH(TODAY())=1, 11, MONTH(TODAY())-2)), INDEX(B5:M5, MONTH(TODAY())) - INDEX(B5:M5, IF(MONTH(TODAY())=1, 12, MONTH(TODAY())-1)) ), "" )/ IFERROR( IF( INDEX(B5:M5, MONTH(TODAY())) = 0, INDEX(B5:M5,MONTH(TODAY())-1), INDEX(B5:M5,MONTH(TODAY())) ), "" )} -> -1.7249968 | Q5: =INDEX(投资收益表[#This Row], MATCH(TEXT(TODAY(),"m") & "月", 投资收益表[#Headers], 0))/INDEX(投资收益表[#Totals], MATCH(TEXT(TODAY(),"m") & "月", 投资收益表[#Headers], 0)) -> 0.18003057 | R5: =IF(AND(投资收益表[[#This Row],[占比]]>=投资收益表[[#This Row],[判定下限]], 投资收益表[[#This Row],[占比]]<=投资收益表[[#This Row],[判定上限]]),"合理","不合理") -> 不合理 | S5: 0 | T5: 0.05
A6: 长桥证券（美港股） | B6: =SUMIFS(ExpJan投资组合[金额],ExpJan投资组合[分类],投资收益表[[#This Row],[投资分类]]) -> 4060.96 | C6: =SUMIFS(ExpFeb投资组合[金额],ExpFeb投资组合[分类],投资收益表[[#This Row],[投资分类]]) -> 367.93 | D6: =SUMIFS(ExpMar投资组合[金额],ExpMar投资组合[分类],投资收益表[[#This Row],[投资分类]]) -> -1445.84 | E6: =SUMIFS(ExpApr投资组合[金额],ExpApr投资组合[分类],投资收益表[[#This Row],[投资分类]]) -> 2811.09 | F6: =SUMIFS(ExpMay投资组合[金额],ExpMay投资组合[分类],投资收益表[[#This Row],[投资分类]]) -> 1088.01 | G6: =SUMIFS(ExpJun投资组合[金额],ExpJun投资组合[分类],投资收益表[[#This Row],[投资分类]]) -> 210.78 | H6: =SUMIFS(ExpJul投资组合[金额],ExpJul投资组合[分类],投资收益表[[#This Row],[投资分类]]) -> 78.74 | I6: =SUMIFS(ExpAug投资组合[金额],ExpAug投资组合[分类],投资收益表[[#This Row],[投资分类]]) -> 631.32 | J6: =SUMIFS(ExpSep投资组合[金额],ExpSep投资组合[分类],投资收益表[[#This Row],[投资分类]]) -> 393.22 | K6: =SUMIFS(ExpOct投资组合[金额],ExpOct投资组合[分类],投资收益表[[#This Row],[投资分类]]) -> 1154.26 | L6: =SUMIFS(ExpNov投资组合[金额],ExpNov投资组合[分类],投资收益表[[#This Row],[投资分类]]) -> 1667.26 | M6: =SUMIFS(ExpDec投资组合[金额],ExpDec投资组合[分类],投资收益表[[#This Row],[投资分类]]) -> 219.6 | N6: =SUBTOTAL(9,投资收益表[[#This Row],[1月]:[12月]]) -> 11237.33 | O6: {=IFERROR( IF( INDEX(B6:M6, MONTH(TODAY())) = 0, INDEX(B6:M6, IF(MONTH(TODAY())=1, 12, MONTH(TODAY())-1)) - INDEX(B6:M6, IF(MONTH(TODAY())=1, 11, MONTH(TODAY())-2)), INDEX(B6:M6, MONTH(TODAY())) - INDEX(B6:M6, IF(MONTH(TODAY())=1, 12, MONTH(TODAY())-1)) ), "" )/ IFERROR( IF( INDEX(B6:M6, MONTH(TODAY())) = 0, INDEX(B6:M6,MONTH(TODAY())-1), INDEX(B6:M6,MONTH(TODAY())) ), "" )} -> -1.5836987 | Q6: =INDEX(投资收益表[#This Row], MATCH(TEXT(TODAY(),"m") & "月", 投资收益表[#Headers], 0))/INDEX(投资收益表[#Totals], MATCH(TEXT(TODAY(),"m") & "月", 投资收益表[#Headers], 0)) -> 0.50398833 | R6: =IF(AND(投资收益表[[#This Row],[占比]]>=投资收益表[[#This Row],[判定下限]], 投资收益表[[#This Row],[占比]]<=投资收益表[[#This Row],[判定上限]]),"合理","不合理") -> 不合理 | S6: 0.6 | T6: 0.8 | W6: 每月消费 | X6: 每年消费 | Y6: 被动收入 年化收益率 | Z6: 被动资产
A7: 比特币 | B7: =SUMIFS(ExpJan投资组合[金额],ExpJan投资组合[分类],投资收益表[[#This Row],[投资分类]]) -> 0.071264 | C7: =SUMIFS(ExpFeb投资组合[金额],ExpFeb投资组合[分类],投资收益表[[#This Row],[投资分类]]) -> 0.071264 | D7: =SUMIFS(ExpMar投资组合[金额],ExpMar投资组合[分类],投资收益表[[#This Row],[投资分类]]) -> 0.071264 | E7: =SUMIFS(ExpApr投资组合[金额],ExpApr投资组合[分类],投资收益表[[#This Row],[投资分类]]) -> 0.071264 | F7: =SUMIFS(ExpMay投资组合[金额],ExpMay投资组合[分类],投资收益表[[#This Row],[投资分类]]) -> 0.071264 | G7: =SUMIFS(ExpJun投资组合[金额],ExpJun投资组合[分类],投资收益表[[#This Row],[投资分类]]) -> 0.071264 | H7: =SUMIFS(ExpJul投资组合[金额],ExpJul投资组合[分类],投资收益表[[#This Row],[投资分类]]) -> 0.071264 | I7: =SUMIFS(ExpAug投资组合[金额],ExpAug投资组合[分类],投资收益表[[#This Row],[投资分类]]) -> 0.071264 | J7: =SUMIFS(ExpSep投资组合[金额],ExpSep投资组合[分类],投资收益表[[#This Row],[投资分类]]) -> 0.071264 | K7: =SUMIFS(ExpOct投资组合[金额],ExpOct投资组合[分类],投资收益表[[#This Row],[投资分类]]) -> 0.071264 | L7: =SUMIFS(ExpNov投资组合[金额],ExpNov投资组合[分类],投资收益表[[#This Row],[投资分类]]) -> 0.071264 | M7: =SUMIFS(ExpDec投资组合[金额],ExpDec投资组合[分类],投资收益表[[#This Row],[投资分类]]) -> 0 | N7: {=IFERROR( IF( INDEX(B7:M7, MONTH(TODAY())) = 0, INDEX(B7:M7, IF(MONTH(TODAY())=1, 12, MONTH(TODAY())-1)) - INDEX(B7:M7, IF(MONTH(TODAY())=1, 11, MONTH(TODAY())-2)), INDEX(B7:M7, MONTH(TODAY())) - INDEX(B7:M7, IF(MONTH(TODAY())=1, 12, MONTH(TODAY())-1)) ), "" )} -> 0 | O7: {=IFERROR( IF( INDEX(B7:M7, MONTH(TODAY())) = 0, INDEX(B7:M7, IF(MONTH(TODAY())=1, 12, MONTH(TODAY())-1)) - INDEX(B7:M7, IF(MONTH(TODAY())=1, 11, MONTH(TODAY())-2)), INDEX(B7:M7, MONTH(TODAY())) - INDEX(B7:M7, IF(MONTH(TODAY())=1, 12, MONTH(TODAY())-1)) ), "" )/ IFERROR( IF( INDEX(B7:M7, MONTH(TODAY())) = 0, INDEX(B7:M7,MONTH(TODAY())-1), INDEX(B7:M7,MONTH(TODAY())) ), "" )} -> 0 | Q7: =INDEX(投资收益表[#This Row], MATCH(TEXT(TODAY(),"m") & "月", 投资收益表[#Headers], 0))/INDEX(投资收益表[#Totals], MATCH(TEXT(TODAY(),"m") & "月", 投资收益表[#Headers], 0)) -> 3.3010932e-05 | R7: =IF(AND(投资收益表[[#This Row],[占比]]>=投资收益表[[#This Row],[判定下限]], 投资收益表[[#This Row],[占比]]<=投资收益表[[#This Row],[判定上限]]),"合理","不合理") -> 合理 | S7: 0 | T7: 0.07 | W7: 2500 | X7: =表11[[#This Row],[每月消费]]*12 -> 30000 | Y7: 0.07 | Z7: =表11[[#This Row],[每年消费]]/表11[[#This Row],[被动收入 年化收益率]] -> 428571.43
A8: 基金（招行） | B8: =SUMIFS(ExpJan投资组合[金额],ExpJan投资组合[分类],投资收益表[[#This Row],[投资分类]]) -> 1661.3 | C8: =SUMIFS(ExpFeb投资组合[金额],ExpFeb投资组合[分类],投资收益表[[#This Row],[投资分类]]) -> 921.04 | D8: =SUMIFS(ExpMar投资组合[金额],ExpMar投资组合[分类],投资收益表[[#This Row],[投资分类]]) -> -1154.66 | E8: =SUMIFS(ExpApr投资组合[金额],ExpApr投资组合[分类],投资收益表[[#This Row],[投资分类]]) -> 1325.68 | F8: =SUMIFS(ExpMay投资组合[金额],ExpMay投资组合[分类],投资收益表[[#This Row],[投资分类]]) -> 682.14 | G8: =SUMIFS(ExpJun投资组合[金额],ExpJun投资组合[分类],投资收益表[[#This Row],[投资分类]]) -> 1217.79 | H8: =SUMIFS(ExpJul投资组合[金额],ExpJul投资组合[分类],投资收益表[[#This Row],[投资分类]]) -> 511.63 | I8: =SUMIFS(ExpAug投资组合[金额],ExpAug投资组合[分类],投资收益表[[#This Row],[投资分类]]) -> 709.94 | J8: =SUMIFS(ExpSep投资组合[金额],ExpSep投资组合[分类],投资收益表[[#This Row],[投资分类]]) -> 290.64 | K8: =SUMIFS(ExpOct投资组合[金额],ExpOct投资组合[分类],投资收益表[[#This Row],[投资分类]]) -> 603.17 | L8: =SUMIFS(ExpNov投资组合[金额],ExpNov投资组合[分类],投资收益表[[#This Row],[投资分类]]) -> -91.75 | M8: =SUMIFS(ExpDec投资组合[金额],ExpDec投资组合[分类],投资收益表[[#This Row],[投资分类]]) -> 289.77 | N8: =SUBTOTAL(9,投资收益表[[#This Row],[1月]:[12月]]) -> 6966.69 | O8: {=IFERROR( IF( INDEX(B8:M8, MONTH(TODAY())) = 0, INDEX(B8:M8, IF(MONTH(TODAY())=1, 12, MONTH(TODAY())-1)) - INDEX(B8:M8, IF(MONTH(TODAY())=1, 11, MONTH(TODAY())-2)), INDEX(B8:M8, MONTH(TODAY())) - INDEX(B8:M8, IF(MONTH(TODAY())=1, 12, MONTH(TODAY())-1)) ), "" )/ IFERROR( IF( INDEX(B8:M8, MONTH(TODAY())) = 0, INDEX(B8:M8,MONTH(TODAY())-1), INDEX(B8:M8,MONTH(TODAY())) ), "" )} -> -0.94341338 | Q8: =INDEX(投资收益表[#This Row], MATCH(TEXT(TODAY(),"m") & "月", 投资收益表[#Headers], 0))/INDEX(投资收益表[#Totals], MATCH(TEXT(TODAY(),"m") & "月", 投资收益表[#Headers], 0)) -> 0.3159811 | R8: =IF(AND(投资收益表[[#This Row],[占比]]>=投资收益表[[#This Row],[判定下限]], 投资收益表[[#This Row],[占比]]<=投资收益表[[#This Row],[判定上限]]),"合理","不合理") -> 合理 | S8: 0 | T8: 0.5 | W8: 2500 | X8: =表11[[#This Row],[每月消费]]*12 -> 30000 | Y8: 0.1 | Z8: =表11[[#This Row],[每年消费]]/表11[[#This Row],[被动收入 年化收益率]] -> 300000
A9: 定期 | B9: =SUMIFS(ExpJan[金额],ExpJan[分类],投资收益表[[#This Row],[投资分类]]) -> 0 | C9: =SUMIFS(ExpFeb[金额],ExpFeb[分类],投资收益表[[#This Row],[投资分类]]) -> 0 | D9: =SUMIFS(ExpMar[金额],ExpMar[分类],投资收益表[[#This Row],[投资分类]]) -> 0 | E9: =SUMIFS(ExpApr[金额],ExpApr[分类],投资收益表[[#This Row],[投资分类]]) -> 0 | F9: =SUMIFS(ExpMay[金额],ExpMay[分类],投资收益表[[#This Row],[投资分类]]) -> 0 | G9: =SUMIFS(ExpJun[金额],ExpJun[分类],投资收益表[[#This Row],[投资分类]]) -> 0 | H9: =SUMIFS(ExpJul[金额],ExpJul[分类],投资收益表[[#This Row],[投资分类]]) -> 0 | I9: =SUMIFS(ExpAug[金额],ExpAug[分类],投资收益表[[#This Row],[投资分类]]) -> 0 | J9: =SUMIFS(ExpSep[金额],ExpSep[分类],投资收益表[[#This Row],[投资分类]]) -> 0 | K9: =SUMIFS(ExpOct[金额],ExpOct[分类],投资收益表[[#This Row],[投资分类]]) -> 0 | L9: =SUMIFS(ExpNov[金额],ExpNov[分类],投资收益表[[#This Row],[投资分类]]) -> 0 | M9: 1365 | N9: =SUBTOTAL(9,投资收益表[[#This Row],[1月]:[12月]]) -> 0 | O9: {=IFERROR( IF( INDEX(B9:M9, MONTH(TODAY())) = 0, INDEX(B9:M9, IF(MONTH(TODAY())=1, 12, MONTH(TODAY())-1)) - INDEX(B9:M9, IF(MONTH(TODAY())=1, 11, MONTH(TODAY())-2)), INDEX(B9:M9, MONTH(TODAY())) - INDEX(B9:M9, IF(MONTH(TODAY())=1, 12, MONTH(TODAY())-1)) ), "" )/ IFERROR( IF( INDEX(B9:M9, MONTH(TODAY())) = 0, INDEX(B9:M9,MONTH(TODAY())-1), INDEX(B9:M9,MONTH(TODAY())) ), "" )} -> #DIV/0! | Q9: =INDEX(投资收益表[#This Row], MATCH(TEXT(TODAY(),"m") & "月", 投资收益表[#Headers], 0))/INDEX(投资收益表[#Totals], MATCH(TEXT(TODAY(),"m") & "月", 投资收益表[#Headers], 0)) -> 0 | R9: =IF(AND(投资收益表[[#This Row],[占比]]>=投资收益表[[#This Row],[判定下限]], 投资收益表[[#This Row],[占比]]<=投资收益表[[#This Row],[判定上限]]),"合理","不合理") -> 合理
A10: 活期 | B10: =SUMIFS(ExpJan[金额],ExpJan[分类],投资收益表[[#This Row],[投资分类]]) -> 0 | C10: =SUMIFS(ExpFeb[金额],ExpFeb[分类],投资收益表[[#This Row],[投资分类]]) -> 13037.809 | D10: =SUMIFS(ExpMar[金额],ExpMar[分类],投资收益表[[#This Row],[投资分类]]) -> 1981.2592 | E10: =SUMIFS(ExpApr[金额],ExpApr[分类],投资收益表[[#This Row],[投资分类]]) -> 55.029167 | F10: =SUMIFS(ExpMay[金额],ExpMay[分类],投资收益表[[#This Row],[投资分类]]) -> 63.899167 | G10: =SUMIFS(ExpJun[金额],ExpJun[分类],投资收益表[[#This Row],[投资分类]]) -> 17757.08 | H10: =SUMIFS(ExpJul[金额],ExpJul[分类],投资收益表[[#This Row],[投资分类]]) -> 12661.761 | I10: =SUMIFS(ExpAug[金额],ExpAug[分类],投资收益表[[#This Row],[投资分类]]) -> 10065.269 | J10: =SUMIFS(ExpSep[金额],ExpSep[分类],投资收益表[[#This Row],[投资分类]]) -> 0 | K10: =SUMIFS(ExpOct[金额],ExpOct[分类],投资收益表[[#This Row],[投资分类]]) -> 0 | L10: =SUMIFS(ExpNov[金额],ExpNov[分类],投资收益表[[#This Row],[投资分类]]) -> 1.379167 | M10: =SUMIFS(ExpDec[金额],ExpDec[分类],投资收益表[[#This Row],[投资分类]]) -> 532.74917 | N10: {=IFERROR( INDEX(B10:M10, MONTH(TODAY())) - INDEX(B10:M10, IF(MONTH(TODAY())=1, 12, MONTH(TODAY())-1)), "")} -> 8.87 | O10: {=IFERROR( IF( INDEX(B10:M10, MONTH(TODAY())) = 0, INDEX(B10:M10, IF(MONTH(TODAY())=1, 12, MONTH(TODAY())-1)) - INDEX(B10:M10, IF(MONTH(TODAY())=1, 11, MONTH(TODAY())-2)), INDEX(B10:M10, MONTH(TODAY())) - INDEX(B10:M10, IF(MONTH(TODAY())=1, 12, MONTH(TODAY())-1)) ), "" )/ IFERROR( IF( INDEX(B10:M10, MONTH(TODAY())) = 0, INDEX(B10:M10,MONTH(TODAY())-1), INDEX(B10:M10,MONTH(TODAY())) ), "" )} -> 0.13881245 | Q10: =INDEX(投资收益表[#This Row], MATCH(TEXT(TODAY(),"m") & "月", 投资收益表[#Headers], 0))/INDEX(投资收益表[#Totals], MATCH(TEXT(TODAY(),"m") & "月", 投资收益表[#Headers], 0)) -> 0.029599392 | R10: =IF(AND(投资收益表[[#This Row],[占比]]>=投资收益表[[#This Row],[判定下限]], 投资收益表[[#This Row],[占比]]<=投资收益表[[#This Row],[判定上限]]),"合理","不合理") -> 不合理
A11: 紧急预备金 | B11: =SUMIFS(ExpJan[金额],ExpJan[分类],投资收益表[[#This Row],[投资分类]]) -> 0 | C11: =SUMIFS(ExpFeb[金额],ExpFeb[分类],投资收益表[[#This Row],[投资分类]]) -> 0 | D11: =SUMIFS(ExpMar[金额],ExpMar[分类],投资收益表[[#This Row],[投资分类]]) -> 0 | E11: =SUMIFS(ExpApr[金额],ExpApr[分类],投资收益表[[#This Row],[投资分类]]) -> 0 | F11: =SUMIFS(ExpMay[金额],ExpMay[分类],投资收益表[[#This Row],[投资分类]]) -> 0 | G11: =SUMIFS(ExpJun[金额],ExpJun[分类],投资收益表[[#This Row],[投资分类]]) -> 0 | H11: =SUMIFS(ExpJul[金额],ExpJul[分类],投资收益表[[#This Row],[投资分类]]) -> 0 | I11: =SUMIFS(ExpAug[金额],ExpAug[分类],投资收益表[[#This Row],[投资分类]]) -> 0 | J11: =SUMIFS(ExpSep[金额],ExpSep[分类],投资收益表[[#This Row],[投资分类]]) -> 0 | K11: =SUMIFS(ExpOct[金额],ExpOct[分类],投资收益表[[#This Row],[投资分类]]) -> 0 | L11: =SUMIFS(ExpNov[金额],ExpNov[分类],投资收益表[[#This Row],[投资分类]]) -> 0 | M11: =SUMIFS(ExpDec[金额],ExpDec[分类],投资收益表[[#This Row],[投资分类]]) -> 0 | N11: {=IFERROR( IF( INDEX(B11:M11, MONTH(TODAY())) = 0, INDEX(B11:M11, IF(MONTH(TODAY())=1, 12, MONTH(TODAY())-1)) - INDEX(B11:M11, IF(MONTH(TODAY())=1, 11, MONTH(TODAY())-2)), INDEX(B11:M11, MONTH(TODAY())) - INDEX(B11:M11, IF(MONTH(TODAY())=1, 12, MONTH(TODAY())-1)) ), "" )} -> 0 | O11: {=IFERROR( IF( INDEX(B11:M11, MONTH(TODAY())) = 0, INDEX(B11:M11, IF(MONTH(TODAY())=1, 12, MONTH(TODAY())-1)) - INDEX(B11:M11, IF(MONTH(TODAY())=1, 11, MONTH(TODAY())-2)), INDEX(B11:M11, MONTH(TODAY())) - INDEX(B11:M11, IF(MONTH(TODAY())=1, 12, MONTH(TODAY())-1)) ), "" )/ IFERROR( IF( INDEX(B11:M11, MONTH(TODAY())) = 0, INDEX(B11:M11,MONTH(TODAY())-1), INDEX(B11:M11,MONTH(TODAY())) ), "" )} -> #DIV/0! | Q11: =INDEX(投资收益表[#This Row], MATCH(TEXT(TODAY(),"m") & "月", 投资收益表[#Headers], 0))/INDEX(投资收益表[#Totals], MATCH(TEXT(TODAY(),"m") & "月", 投资收益表[#Headers], 0)) -> 0 | R11: =IF(AND(投资收益表[[#This Row],[占比]]>=投资收益表[[#This Row],[判定下限]], 投资收益表[[#This Row],[占比]]<=投资收益表[[#This Row],[判定上限]]),"合理","不合理") -> 合理 | S11: 0 | T11: 0.1
A12: {=IFERROR( _xlfn.LET( _xlpm.data, B12:M12, _xlpm.nonZeroData, IF(_xlpm.data>0, _xlpm.data, ""), _xlpm.minVal, MIN(_xlpm.nonZeroData), _xlpm.maxVal, MAX(_xlpm.data), _xlpm.startPos, MATCH(_xlpm.minVal, _xlpm.nonZeroData, 0), _xlpm.endPos, MATCH(_xlpm.maxVal, _xlpm.data, 0), _xlpm.startDate, INDEX(B2:M2, _xlpm.startPos), _xlpm.endDate, INDEX(B2:M2, _xlpm.endPos), IF(_xlpm.endDate < _xlpm.startDate, "", (_xlpm.maxVal / _xlpm.minVal) -1 ) ), "" )} -> 13.535041 | B12: =SUBTOTAL(109,投资收益表[1月]) -> 7512 | C12: =SUBTOTAL(109,投资收益表[2月]) -> 1971.63 | D12: =SUBTOTAL(109,投资收益表[3月]) -> -3159.07 | E12: =SUBTOTAL(109,投资收益表[4月]) -> 5195.84 | F12: =SUBTOTAL(109,投资收益表[5月]) -> 2158.8 | G12: =SUBTOTAL(109,投资收益表[6月]) -> 2055.41 | H12: =SUBTOTAL(109,投资收益表[7月]) -> 763.35 | I12: =SUBTOTAL(109,投资收益表[8月]) -> 1282.23 | J12: =SUBTOTAL(109,投资收益表[9月]) -> 516.82 | K12: =SUBTOTAL(109,投资收益表[10月]) -> 2841.37 | L12: =SUBTOTAL(109,投资收益表[11月]) -> 734.51 | M12: =SUBTOTAL(109,投资收益表[12月]) -> 518.44 | N12: =N5+N6+N8+N9 -> 22391.33 | O12: {=IFERROR( IF( INDEX(B12:M12, MONTH(TODAY())) = 0, INDEX(B12:M12, IF(MONTH(TODAY())=1, 12, MONTH(TODAY())-1)) - INDEX(B12:M12, IF(MONTH(TODAY())=1, 11, MONTH(TODAY())-2)), INDEX(B12:M12, MONTH(TODAY())) - INDEX(B12:M12, IF(MONTH(TODAY())=1, 12, MONTH(TODAY())-1)) ), "" )/ IFERROR( IF( INDEX(B12:M12, MONTH(TODAY())) = 0, INDEX(B12:M12,MONTH(TODAY())-1), INDEX(B12:M12,MONTH(TODAY())) ), "" )} -> -1.4068186 | P12: {=IFERROR( _xlfn.LET( _xlpm.data, B12:M12, _xlpm.nonZeroData, IF(_xlpm.data>0, _xlpm.data, ""), _xlpm.minVal, MIN(_xlpm.nonZeroData), _xlpm.maxVal, MAX(_xlpm.data), _xlpm.startPos, MATCH(_xlpm.minVal, _xlpm.nonZeroData, 0), _xlpm.endPos, MATCH(_xlpm.maxVal, _xlpm.data, 0), _xlpm.startDate, INDEX(B2:M2, _xlpm.startPos), _xlpm.endDate, INDEX(B2:M2, _xlpm.endPos), IF(_xlpm.endDate < _xlpm.startDate, "", _xlfn.LET( _xlpm.months, DATEDIF(_xlpm.startDate, _xlpm.endDate, "m") +1, (_xlpm.maxVal / _xlpm.minVal) ^ (12/_xlpm.months) -1 ) ) ), "" )} -> 615.30976 | Q12: =SUBTOTAL(109,投资收益表[占比]) -> 1 | S12: =SUBTOTAL(109,投资收益表[判定下限]) -> 0.6 | T12: =SUBTOTAL(109,投资收益表[判定上限]) -> 1.35
A13: 环比增长C | B13: =投资收益表[[#Totals],[1月]]/投资收益表[[#Totals],[12月]]-1 -> 13.489623 | C13: =IFERROR( _xlfn.LET( _xlpm.result, 投资收益表[[#Totals],[2月]]/投资收益表[[#Totals],[1月]]-1, IF(OR(_xlpm.result=0, _xlpm.result=-1), 0, _xlpm.result) ), 0 ) -> -0.73753594 | D13: =IFERROR( _xlfn.LET( _xlpm.result, 投资收益表[[#Totals],[3月]]/投资收益表[[#Totals],[2月]]-1, IF(OR(_xlpm.result=0, _xlpm.result=-1), 0, _xlpm.result) ), 0 ) -> -2.6022631 | E13: =IFERROR( _xlfn.LET( _xlpm.result, 投资收益表[[#Totals],[4月]]/投资收益表[[#Totals],[3月]]-1, IF(OR(_xlpm.result=0, _xlpm.result=-1), 0, _xlpm.result) ), 0 ) -> -2.6447372 | F13: =IFERROR( _xlfn.LET( _xlpm.result, 投资收益表[[#Totals],[5月]]/投资收益表[[#Totals],[4月]]-1, IF(OR(_xlpm.result=0, _xlpm.result=-1), 0, _xlpm.result) ), 0 ) -> -0.58451376 | G13: =IFERROR( _xlfn.LET( _xlpm.result, 投资收益表[[#Totals],[6月]]/投资收益表[[#Totals],[5月]]-1, IF(OR(_xlpm.result=0, _xlpm.result=-1), 0, _xlpm.result) ), 0 ) -> -0.047892348 | H13: =IFERROR( _xlfn.LET( _xlpm.result, 投资收益表[[#Totals],[7月]]/投资收益表[[#Totals],[6月]]-1, IF(OR(_xlpm.result=0, _xlpm.result=-1), 0, _xlpm.result) ), 0 ) -> -0.62861424 | I13: =IFERROR( _xlfn.LET( _xlpm.result, 投资收益表[[#Totals],[8月]]/投资收益表[[#Totals],[7月]]-1, IF(OR(_xlpm.result=0, _xlpm.result=-1), 0, _xlpm.result) ), 0 ) -> 0.67974062 | J13: =IFERROR( _xlfn.LET( _xlpm.result, 投资收益表[[#Totals],[9月]]/投资收益表[[#Totals],[8月]]-1, IF(OR(_xlpm.result=0, _xlpm.result=-1), 0, _xlpm.result) ), 0 ) -> -0.59693659 | K13: =IFERROR( _xlfn.LET( _xlpm.result, 投资收益表[[#Totals],[10月]]/投资收益表[[#Totals],[9月]]-1, IF(OR(_xlpm.result=0, _xlpm.result=-1), 0, _xlpm.result) ), 0 ) -> 4.4977942 | L13: =IFERROR( _xlfn.LET( _xlpm.result, 投资收益表[[#Totals],[11月]]/投资收益表[[#Totals],[10月]]-1, IF(OR(_xlpm.result=0, _xlpm.result=-1), 0, _xlpm.result) ), 0 ) -> -0.74149442 | M13: =IFERROR( _xlfn.LET( _xlpm.result, 投资收益表[[#Totals],[12月]]/投资收益表[[#Totals],[11月]]-1, IF(OR(_xlpm.result=0, _xlpm.result=-1), 0, _xlpm.result) ), 0 ) -> -0.2941689 | N13: =SUMIF(B13:M13, ">0") / COUNTIF(B13:M13, ">0") -> 6.2223858 | O13: =投资收益表[[#Totals],[全年统计]]/(AVERAGE(资产摘要[[#Totals],[1月]:[12月]])) -> 0.059215481
B15: 基金简称 | C15: 基金代码 | D15: 持有起始日期 | E15: 持有天数 | F15: %基金N日净值增长率 | G15: 账面价值 | H15: 每2天定投 | I15: 每月平均 | J15: 当前比例 | K15: 推荐比例
B16: =[1]!EM_F_INFO_NAME(C16) -> Refreshing | C16: 110017 | D16: 45631 | E16: =([1]!EM_DATECOUNT(D16,$C$23,"CNSESH")) -> #NAME? | F16: =[1]!EM_F_NQ_NAVCHANGE(基金[[#This Row],[基金代码]],-E16) -> #NAME? | G16: 64765.22 | H16: 160 | I16: 200 | J16: =基金[[#This Row],[账面价值]]/基金[[#Totals],[账面价值]] -> 0.95984721 | K16: 0.5
B17: =[1]!EM_F_INFO_NAME(C17) -> Refreshing | C17: 270042 | D17: 45632 | E17: =([1]!EM_DATECOUNT(D17,$C$23,"CNSESH")) -> #NAME? | F17: =[1]!EM_F_NQ_NAVCHANGE(基金[[#This Row],[基金代码]],-E17) -> #NAME? | G17: 0 | H17: 100 | I17: =基金[[#This Row],[每2天定投]]*11 -> 1100 | J17: =基金[[#This Row],[账面价值]]/基金[[#Totals],[账面价值]] -> 0 | K17: 0.15
B18: =[1]!EM_F_INFO_NAME(C18) -> Refreshing | C18: 007280 | D18: 45895 | E18: =([1]!EM_DATECOUNT(D18,$C$23,"CNSESH")) -> #NAME? | F18: =[1]!EM_F_NQ_NAVCHANGE(基金[[#This Row],[基金代码]],-E18) -> #NAME? | G18: 204.93 | H18: 100 | I18: =基金[[#This Row],[每2天定投]]*11 -> 1100 | J18: =基金[[#This Row],[账面价值]]/基金[[#Totals],[账面价值]] -> 0.0030371469 | K18: 0.15
B19: =[1]!EM_F_INFO_NAME(C19) -> Refreshing | C19: 007721 | D19: 45940 | E19: =([1]!EM_DATECOUNT(D19,$C$23,"CNSESH")) -> #NAME? | F19: =[1]!EM_F_NQ_NAVCHANGE(基金[[#This Row],[基金代码]],-E19) -> #NAME? | G19: 2405.47 | H19: 100 | I19: =基金[[#This Row],[每2天定投]]*11 -> 1100 | J19: =基金[[#This Row],[账面价值]]/基金[[#Totals],[账面价值]] -> 0.035650055 | K19: 0.15
B20: =[1]!EM_F_INFO_NAME(C20) -> Refreshing | C20: 000390 | D20: 45904 | E20: =([1]!EM_DATECOUNT(D20,$C$23,"CNSESH")) -> #NAME? | F20: =[1]!EM_F_NQ_NAVCHANGE(基金[[#This Row],[基金代码]],-E20) -> #NAME? | G20: 98.89 | H20: 26.66 | I20: =基金[[#This Row],[每2天定投]]*11 -> 293.26 | J20: =基金[[#This Row],[账面价值]]/基金[[#Totals],[账面价值]] -> 0.0014655905 | K20: 0.05
B21: =[1]!EM_F_INFO_NAME(C21) -> Refreshing | C21: 000216 | D21: 45924 | E21: =([1]!EM_DATECOUNT(D21,$C$23,"CNSESH")) -> #NAME? | F21: =[1]!EM_F_NQ_NAVCHANGE(基金[[#This Row],[基金代码]],-E21) -> #NAME? | G21: 966.87 | H21: 0 | I21: =基金[[#This Row],[每2天定投]]*11 -> 0 | J21: =基金[[#This Row],[每2天定投]]/基金[[#Totals],[每2天定投]] -> 0 | K21: 0
B22: =[1]!EM_F_INFO_NAME(C22) -> Refreshing | C22: 096001 | D22: 45902 | E22: =([1]!EM_DATECOUNT(D22,$C$23,"CNSESH")) -> #NAME? | F22: =[1]!EM_F_NQ_NAVCHANGE(基金[[#This Row],[基金代码]],-E22) -> #NAME? | G22: 5270.51 | H22: 0.01 | I22: =基金[[#This Row],[每2天定投]]*11 -> 0.11 | J22: =基金[[#This Row],[每2天定投]]/基金[[#Totals],[每2天定投]] -> 2.0548227e-05 | K22: 0
B23: 汇总 | C23: =TODAY() -> 46166 | G23: =SUBTOTAL(109,基金[账面价值]) -> 67474.51 | H23: =SUBTOTAL(109,基金[每2天定投]) -> 486.66 | I23: =SUBTOTAL(109,基金[每月平均]) -> 3793.26 | J23: =SUBTOTAL(109,基金[当前比例]) -> 1 | K23: =SUBTOTAL(109,基金[推荐比例]) -> 1
B25: 公司 | C25: 代码 | D25: 股份 | E25: 成本价 | F25: 当前价格 | G25: 变化（百分比） | H25: 持仓成本 | I25: 账面价值 | J25: 当前比例 | K25: 推荐比例
B26: #VALUE! | C26: SPY | D26: 3 | E26: 664.49 | F26: =_FV(美股投资表[[#This Row],[公司]],"Price") -> 662.23 | G26: =美股投资表[[#This Row],[账面价值]]/美股投资表[[#This Row],[持仓成本]]-1 -> -0.0034011046 | H26: =美股投资表[[#This Row],[股份]]*美股投资表[[#This Row],[成本价]] -> 1993.47 | I26: =美股投资表[[#This Row],[股份]]*美股投资表[[#This Row],[当前价格]] -> 1986.69 | J26: =IFERROR(I26/SUBTOTAL(109,美股投资表[账面价值]),"") -> 0.46088161 | K26: 0.5
B27: #VALUE! | C27: SCHD | D27: 40 | E27: 26.523 | F27: =_FV(美股投资表[[#This Row],[公司]],"Price") -> 26.87 | G27: =美股投资表[[#This Row],[账面价值]]/美股投资表[[#This Row],[持仓成本]]-1 -> 0.013082985 | H27: =美股投资表[[#This Row],[股份]]*美股投资表[[#This Row],[成本价]] -> 1060.92 | I27: =美股投资表[[#This Row],[股份]]*美股投资表[[#This Row],[当前价格]] -> 1074.8 | J27: =IFERROR(I27/SUBTOTAL(109,美股投资表[账面价值]),"") -> 0.24933712 | K27: 0.2
B28: #VALUE! | C28: QQQ | D28: 2 | E28: 608.095 | F28: =_FV(美股投资表[[#This Row],[公司]],"Price") -> 624.5699 | G28: =美股投资表[[#This Row],[账面价值]]/美股投资表[[#This Row],[持仓成本]]-1 -> 0.027092642 | H28: =美股投资表[[#This Row],[股份]]*美股投资表[[#This Row],[成本价]] -> 1216.19 | I28: =美股投资表[[#This Row],[股份]]*美股投资表[[#This Row],[当前价格]] -> 1249.1398 | J28: =IFERROR(I28/SUBTOTAL(109,美股投资表[账面价值]),"") -> 0.28978128 | K28: 0.3
B29: #VALUE! | C29: DGRO | D29: 11 | E29: 64.909 | F29: =_FV(美股投资表[[#This Row],[公司]],"Price") -> 68.07 | G29: =美股投资表[[#This Row],[账面价值]]/美股投资表[[#This Row],[持仓成本]]-1 -> 0.048698948 | H29: =美股投资表[[#This Row],[股份]]*美股投资表[[#This Row],[成本价]] -> 713.999 | I29: =美股投资表[[#This Row],[股份]]*美股投资表[[#This Row],[当前价格]] -> 748.77 | J29: =IFERROR(I29/SUBTOTAL(109,美股投资表[账面价值]),"") -> 0.17370316 | K29: 0
B30: =[1]!EM_S_INFO_HKSHARENAME(C30) -> Refreshing | C30: 00883 | D30: 1000 | E30: 2.38 | F30: =[1]!EM_HKS_DQ_CLOSE(C30,"N","3","1") -> #NAME? | G30: =美股投资表[[#This Row],[账面价值]]/美股投资表[[#This Row],[持仓成本]]-1 -> #NAME? | H30: =美股投资表[[#This Row],[股份]]*美股投资表[[#This Row],[成本价]] -> 2380 | I30: =美股投资表[[#This Row],[股份]]*美股投资表[[#This Row],[当前价格]] -> #NAME? | J30: =IFERROR(I30/SUBTOTAL(109,美股投资表[账面价值]),"")
B31: 汇总 | G31: =美股投资表[[#Totals],[账面价值]]/美股投资表[[#Totals],[持仓成本]]-1 -> 0.0093780704 | H31: =SUBTOTAL(109,美股投资表[持仓成本]) -> 4270.58 | I31: =SUBTOTAL(109,美股投资表[账面价值]) -> 4310.6298
B34: 公司 | C34: 证券代码 | D34: 股份 | E34: 成本价 | F34: 当前价格 | G34: 变化（百分比） | H34: 持仓成本 | I34: 账面价值 | J34: 买入理由 | K34: 推荐比例
B35: =[1]!EM_S_INFO_COMPNAME(C35) -> Refreshing | C35: 601919 | D35: 1400 | E35: 14.004 | F35: =[1]!EM_S_DQ_CLOSE(C35,"N","1") -> Refreshing | G35: =A股投资表[[#This Row],[账面价值]]/A股投资表[[#This Row],[持仓成本]]-1 -> #VALUE! | H35: =A股投资表[[#This Row],[股份]]*A股投资表[[#This Row],[成本价]] -> 19605.6 | I35: =A股投资表[[#This Row],[股份]]*A股投资表[[#This Row],[当前价格]] -> #VALUE!
B36: =[1]!EM_S_INFO_COMPNAME(C36) -> Refreshing | C36: 600060 | D36: 300 | E36: 22.797 | F36: =[1]!EM_S_DQ_CLOSE(C36,"N","1") -> Refreshing | G36: =A股投资表[[#This Row],[账面价值]]/A股投资表[[#This Row],[持仓成本]]-1 -> #VALUE! | H36: =A股投资表[[#This Row],[股份]]*A股投资表[[#This Row],[成本价]] -> 6839.1 | I36: =A股投资表[[#This Row],[股份]]*A股投资表[[#This Row],[当前价格]] -> #VALUE!
B37: =[1]!EM_S_INFO_COMPNAME(C37) -> Refreshing | C37: 300770 | D37: 0 | F37: =[1]!EM_S_DQ_CLOSE(C37,"N","1") -> Refreshing | G37: =A股投资表[[#This Row],[账面价值]]/A股投资表[[#This Row],[持仓成本]]-1 -> #VALUE! | H37: =A股投资表[[#This Row],[股份]]*A股投资表[[#This Row],[成本价]] -> 0 | I37: =A股投资表[[#This Row],[股份]]*A股投资表[[#This Row],[当前价格]] -> #VALUE! | J37: 1.营业收入： 1）IPTV业务维持8.3亿左右规模 2）互联网视听业务维持5%增长，>6.33亿 2.分红回报和管理层决策 3）股利支付率持续>70%，股息率>4.5% 3.政策支持 4）到27年年底免税政策25%免税 4.市场地位: 7个牌照持有者之一（电视内容管控商） | K37: 内在价值计算出是40元 安全边际： 20%→32元→PE11.7→2w投入 30%→28元→PE10.2→3w投入 40%→24元→PE8.8→4w投入 考虑2028年税收政策取消后 内在价值仅剩下 28元，可基于此重新估算
B38: =[1]!EM_S_INFO_COMPNAME(C38) -> Refreshing | C38: 600941 | D38: 100 | E38: 94.241 | F38: =[1]!EM_S_DQ_CLOSE(C38,"N","1") -> Refreshing | G38: =A股投资表[[#This Row],[账面价值]]/A股投资表[[#This Row],[持仓成本]]-1 -> #VALUE! | H38: =A股投资表[[#This Row],[股份]]*A股投资表[[#This Row],[成本价]] -> 9424.1 | I38: =A股投资表[[#This Row],[股份]]*A股投资表[[#This Row],[当前价格]] -> #VALUE!
B39: 汇总 | G39: =A股投资表[[#Totals],[账面价值]]/A股投资表[[#Totals],[持仓成本]]-1 -> #VALUE! | H39: =SUBTOTAL(109,A股投资表[持仓成本]) -> 35868.8 | I39: =SUBTOTAL(109,A股投资表[账面价值]) -> #VALUE!
B42: 列1 | C42: 指标名称 | D42: 严苛指标 | E42: 列4 | F42: 放宽指标 | G42: 列6 | H42: 列7
C43: XX年自由现金流倍数
C44: 净资产收益率ROE | D44: 连续3年大于10%
C45: 加权净资产收益率 | D45: >10%
C46: 销售毛利率 | D46: 筛选>50%
C47: 销售净利率 | D47: 筛选>10%
...

Sheet 1 月
A1: 1 月支出 | D1: 摘要 | E1: 提示
A2: 日期 | B2: PO# | C2: 汇率（特殊-CNY） | D2: 特殊币种 | E2: 金额 | F2: 类别 | G2: 描述 | H2: 分类
B3: A-12345 | E3: 192935.76 | F3: 招商银行
B4: A-12346 | E4: 2119.37 | F4: 中国银行
E5: 41299.21 | F5: 东方财富
C6: #VALUE! | D6: 0.01 | E6: {=ExpJan[[#This Row],[特殊币种]]*_FV(ExpJan[[#This Row],[汇率（特殊-CNY）]],"Price")} -> 0.009167 | F6: 中银香港
C7: 6.83 | D7: 1295.18 | E7: =ExpJan[[#This Row],[汇率（特殊-CNY）]]*ExpJan[[#This Row],[特殊币种]] -> 8846.0794 | F7: 币安Biance
E8: 46588.66 | F8: 长桥证券
E9: 46095 | F9: 东莞农村商业银行
E10: =134.84+0.02 -> 134.86 | F10: 微信
E11: 0.2 | F11: 支付宝
A12: 汇总 | E12: =SUBTOTAL(109,ExpJan[金额]) -> 338019.15
A14: 日期 | B14: PO# | C14: 汇率（特殊-CNY） | D14: 特殊币种 | E14: 金额 | F14: 类别 | G14: 描述 | H14: 分类
E15: 1789.74 | F15: 东方财富（A股） | G15: 填写收益 | H15: 东方财富（A股）
E16: 4060.96 | F16: 长桥证券（美港股） | H16: 长桥证券（美港股）
C17: #VALUE! | D17: 0.01 | E17: {=ExpJan投资组合[[#This Row],[特殊币种]]*_FV(ExpJan投资组合[[#This Row],[汇率（特殊-CNY）]],"Price")} -> 0.071264 | F17: 比特币 | H17: 比特币
E18: 1661.3 | F18: 基金（招行） | H18: 基金（招行）
A19: 汇总 | E19: =SUBTOTAL(109,ExpJan投资组合[金额]) -> 7512.0713

Sheet 2 月
A1: 2 月支出 | F1: 摘要 | G1: 提示
A2: 日期 | B2: PO# | C2: 汇率（特殊-CNY） | D2: 特殊币种 | E2: 金额 | F2: 类别 | G2: 描述 | H2: 分类
E3: 260187.53 | F3: 招商银行 | G3: TRUE | H3: 基金
E4: 2084.81 | F4: 中国银行 | G4: TRUE | H4: 活期
E5: 42623.14 | F5: 东方财富 | G5: TRUE | H5: 股票
C6: #VALUE! | D6: 0.01 | E6: {=ExpFeb[[#This Row],[特殊币种]]*_FV(ExpFeb[[#This Row],[汇率（特殊-CNY）]],"Price")} -> 0.009167 | F6: 中银香港 | G6: TRUE | H6: 活期
C7: 6.84 | D7: 1100.94 | E7: =ExpFeb[[#This Row],[汇率（特殊-CNY）]]*ExpFeb[[#This Row],[特殊币种]] -> 7530.4296 | F7: 币安Biance | G7: TRUE | H7: 比特币
E8: 48786.92 | F8: 长桥证券 | G8: TRUE | H8: 股票
E9: 0.01 | F9: 东莞农村商业银行 | G9: TRUE | H9: 定期等安全投资
E10: =668.45+197.76 -> 866.21 | F10: 微信 | G10: TRUE | H10: 活期
E11: 10086.78 | F11: 支付宝 | G11: TRUE | H11: 活期
A12: 汇总 | E12: =SUBTOTAL(109,ExpFeb[金额]) -> 372165.84
A14: 日期 | B14: PO# | C14: 汇率（特殊-CNY） | D14: 特殊币种 | E14: 金额 | F14: 类别 | G14: 描述 | H14: 分类
E15: 682.66 | F15: 东方财富（A股） | G15: 填写收益 | H15: 东方财富（A股）
E16: 367.93 | F16: 长桥证券（美港股） | H16: 长桥证券（美港股）
C17: #VALUE! | D17: 0.01 | E17: {=ExpFeb投资组合[[#This Row],[特殊币种]]*_FV(ExpFeb投资组合[[#This Row],[汇率（特殊-CNY）]],"Price")} -> 0.071264 | F17: 比特币 | H17: 比特币
E18: 921.04 | F18: 基金（招行） | H18: 基金（招行）
A19: 汇总 | E19: =SUBTOTAL(109,ExpFeb投资组合[金额]) -> 1971.7013

Sheet 3 月
A1: 3 月支出 | D1: 摘要 | E1: 提示
A2: 日期 | B2: PO# | C2: 汇率（特殊-CNY） | D2: 特殊币种 | E2: 金额 | F2: 类别 | G2: 描述 | H2: 分类
B3: A-12345 | E3: 429074.87 | F3: 招商银行 | G3: 补给 | H3: 基金
B4: A-12346 | E4: 1973.89 | F4: 中国银行 | H4: 活期
E5: 54889.23 | F5: 东方财富 | H5: 股票
C6: #VALUE! | D6: 0.01 | E6: {=ExpMar[[#This Row],[特殊币种]]*_FV(ExpMar[[#This Row],[汇率（特殊-CNY）]],"Price")} -> 0.009167 | F6: 中银香港 | H6: 活期
E7: 7845.43 | F7: 币安Biance | H7: 比特币
E8: 48266.09 | F8: 长桥证券 | H8: 股票
E9: 0.01 | F9: 东莞农村商业银行 | H9: 定期等安全投资
E10: =4.08+3.26 -> 7.34 | F10: 微信 | H10: 活期
E11: 0.02 | F11: 支付宝 | H11: 活期
A12: 汇总 | E12: =SUBTOTAL(109,ExpMar[金额]) -> 542056.89
A14: 日期 | B14: PO# | C14: 汇率（特殊-CNY） | D14: 特殊币种 | E14: 金额 | F14: 类别 | G14: 描述 | H14: 分类
E15: -558.57 | F15: 东方财富（A股） | G15: 填写收益 | H15: 东方财富（A股）
E16: -1445.84 | F16: 长桥证券（美港股） | H16: 长桥证券（美港股）
C17: #VALUE! | D17: 0.01 | E17: {=ExpMar投资组合[[#This Row],[特殊币种]]*_FV(ExpMar投资组合[[#This Row],[汇率（特殊-CNY）]],"Price")} -> 0.071264 | F17: 比特币 | H17: 比特币
E18: -1154.66 | F18: 基金（招行） | H18: 基金（招行）
A19: 汇总 | E19: =SUBTOTAL(109,ExpMar投资组合[金额]) -> -3158.9987

Sheet 4 月
A1: 4 月支出 | F1: 摘要 | G1: 提示
A2: 日期 | B2: PO# | C2: 汇率（特殊-CNY） | D2: 特殊币种 | E2: 金额 | F2: 类别 | G2: 描述 | H2: 分类
E3: 353671.01 | F3: 招商银行 | H3: 基金
E4: 53.08 | F4: 中国银行 | H4: 活期
E5: 140024.49 | F5: 东方财富 | H5: 股票
C6: #VALUE! | D6: 0.01 | E6: {=_FV(ExpApr[[#This Row],[汇率（特殊-CNY）]],"Price")*ExpApr[[#This Row],[特殊币种]]} -> 0.009167 | F6: 中银香港 | H6: 活期
C7: 7.29 | D7: 1229.17 | E7: 7988.15 | F7: 币安Biance | G7: 使用首页显示 | H7: 比特币
E8: 48651.67 | F8: 长桥证券 | G8: 使用首页显示 | H8: 股票
E9: 0 | F9: 东莞农村商业银行 | H9: 定期等安全投资
E10: =1.64+0.26 -> 1.9 | F10: 微信 | H10: 活期
E11: 0.04 | F11: 支付宝 | H11: 活期
A12: 汇总 | E12: =SUBTOTAL(109,ExpApr[金额]) -> 550390.35
A14: 日期 | B14: PO# | C14: 汇率（特殊-CNY） | D14: 特殊币种 | E14: 金额 | F14: 类别 | G14: 描述 | H14: 分类
E15: 1059.07 | F15: 东方财富（A股） | G15: 填写收益 | H15: 东方财富（A股）
E16: 2811.09 | F16: 长桥证券（美港股） | H16: 长桥证券（美港股）
C17: #VALUE! | D17: 0.01 | E17: {=ExpApr投资组合[[#This Row],[特殊币种]]*_FV(ExpApr投资组合[[#This Row],[汇率（特殊-CNY）]],"Price")} -> 0.071264 | F17: 比特币 | H17: 比特币
E18: 1325.68 | F18: 基金（招行） | H18: 基金（招行）
A19: 汇总 | E19: =SUBTOTAL(109,ExpApr投资组合[金额]) -> 5195.9113

Sheet 5 月
A1: 5 月支出 | F1: 摘要 | G1: 提示
A2: 日期 | B2: PO# | C2: 汇率（特殊-CNY） | D2: 特殊币种 | E2: 金额 | F2: 类别 | G2: 描述 | H2: 分类
B3: A-12345 | E3: 372604.37 | F3: 招商银行 | H3: 基金
B4: A-12346 | E4: 52.95 | F4: 中国银行 | H4: 活期
E5: 140296.64 | F5: 东方财富 | H5: 股票
C6: #VALUE! | D6: 0.01 | E6: {=_FV(ExpMay[[#This Row],[汇率（特殊-CNY）]],"Price")*ExpMay[[#This Row],[特殊币种]]} -> 0.009167 | F6: 中银香港 | H6: 活期
C7: 7.21 | D7: 1268.88 | E7: 8321.18 | F7: 币安Biance | H7: 比特币
E8: 49834.35 | F8: 长桥证券 | H8: 股票
E9: 0 | F9: 东莞农村商业银行 | H9: 定期等安全投资
E10: =0.26+9.64 -> 9.9 | F10: 微信 | H10: 活期
E11: 1.04 | F11: 支付宝 | H11: 活期
A12: 汇总 | E12: =SUBTOTAL(109,ExpMay[金额]) -> 571120.44
A14: 日期 | B14: PO# | C14: 汇率（特殊-CNY） | D14: 特殊币种 | E14: 金额 | F14: 类别 | G14: 描述 | H14: 分类
E15: 388.65 | F15: 东方财富（A股） | G15: 填写收益 | H15: 东方财富（A股）
E16: 1088.01 | F16: 长桥证券（美港股） | H16: 长桥证券（美港股）
C17: #VALUE! | D17: 0.01 | E17: {=ExpMay投资组合[[#This Row],[特殊币种]]*_FV(ExpMay投资组合[[#This Row],[汇率（特殊-CNY）]],"Price")} -> 0.071264 | F17: 比特币 | H17: 比特币
E18: 682.14 | F18: 基金（招行） | H18: 基金（招行）
A19: 汇总 | E19: =SUBTOTAL(109,ExpMay投资组合[金额]) -> 2158.8713

Sheet 6 月
A1: 6 月支出 | F1: 摘要 | G1: 提示
A2: 日期 | B2: PO# | C2: 汇率（特殊-CNY） | D2: 特殊币种 | E2: 金额 | F2: 类别 | G2: 描述 | H2: 分类
E3: 153397.45 | F3: 招商银行 | G3: 补给 | H3: 基金
E4: 10458.89 | F4: 中国银行 | H4: 活期
E5: 21009.23 | F5: 东方财富 | H5: 股票
C6: #VALUE! | D6: 800 | E6: {=_FV(ExpJun[[#This Row],[汇率（特殊-CNY）]],"Price")*ExpJun[[#This Row],[特殊币种]]} -> 5701.12 | F6: 中银香港 | H6: 活期
C7: 7.18 | D7: 1269.85 | E7: =ExpJun[[#This Row],[汇率（特殊-CNY）]]*ExpJun[[#This Row],[特殊币种]] -> 9117.523 | F7: 币安Biance | H7: 比特币
E8: 8484.92 | F8: 长桥证券 | H8: 股票
E9: 81466.09 | F9: 东莞农村商业银行 | H9: 定期等安全投资
E10: =1168.89+117.2 -> 1286.09 | F10: 微信 | H10: 活期
E11: 310.98 | F11: 支付宝 | H11: 活期
A12: 汇总 | E12: =SUBTOTAL(109,ExpJun[金额]) -> 291232.29
A14: 日期 | B14: PO# | C14: 汇率（特殊-CNY） | D14: 特殊币种 | E14: 金额 | F14: 类别 | G14: 描述 | H14: 分类
E15: 626.84 | F15: 东方财富（A股） | G15: 填写收益 | H15: 东方财富（A股）
E16: 210.78 | F16: 长桥证券（美港股） | H16: 长桥证券（美港股）
C17: #VALUE! | D17: 0.01 | E17: {=ExpJun投资组合[[#This Row],[特殊币种]]*_FV(ExpJun投资组合[[#This Row],[汇率（特殊-CNY）]],"Price")} -> 0.071264 | F17: 比特币 | H17: 比特币
E18: 1217.79 | F18: 基金（招行） | H18: 基金（招行）
A19: 汇总 | E19: =SUBTOTAL(109,ExpJun投资组合[金额]) -> 2055.4813

Sheet 7 月
A1: 7 月支出 | F1: 摘要 | G1: 提示
A2: 日期 | B2: PO# | C2: 汇率（特殊-CNY） | D2: 特殊币种 | E2: 金额 | F2: 类别 | G2: 描述 | H2: 分类
E3: 162079.94 | F3: 招商银行 | G3: 补给 | H3: 基金
E4: 12612.22 | F4: 中国银行 | H4: 活期
E5: 20932.77 | F5: 东方财富 | H5: 股票
C6: #VALUE! | D6: 0.01 | E6: {=_FV(ExpJul[[#This Row],[汇率（特殊-CNY）]],"Price")*ExpJul[[#This Row],[特殊币种]]} -> 0.071264 | F6: 中银香港 | H6: 活期
C7: 7.15 | D7: 1273.25 | E7: =ExpJul[[#This Row],[特殊币种]]*ExpJul[[#This Row],[汇率（特殊-CNY）]] -> 9103.7375 | F7: 币安Biance | H7: 比特币
E8: =8840+5744.32 -> 14584.32 | F8: 长桥证券 | H8: 股票
E9: 81503.45 | F9: 东莞农村商业银行 | H9: 定期等安全投资
E10: =1.23+1.7 -> 2.93 | F10: 微信 | H10: 活期
E11: 46.54 | F11: 支付宝 | H11: 活期
A12: 汇总 | E12: =SUBTOTAL(109,ExpJul[金额]) -> 300865.98
A14: 日期 | B14: PO# | C14: 汇率（特殊-CNY） | D14: 特殊币种 | E14: 金额 | F14: 类别 | G14: 描述 | H14: 分类
E15: 172.98 | F15: 东方财富（A股） | G15: 填写收益 | H15: 东方财富（A股）
E16: 78.74 | F16: 长桥证券（美港股） | H16: 长桥证券（美港股）
C17: #VALUE! | D17: 0.01 | E17: {=ExpJul投资组合[[#This Row],[特殊币种]]*_FV(ExpJul投资组合[[#This Row],[汇率（特殊-CNY）]],"Price")} -> 0.071264 | F17: 比特币 | H17: 比特币
E18: 511.63 | F18: 基金（招行） | H18: 基金（招行）
A19: 汇总 | E19: =SUBTOTAL(109,ExpJul投资组合[金额]) -> 763.42126

Sheet 8 月
A1: 8 月资产统计 | F1: 摘要 | G1: 提示
A2: 日期 | B2: PO# | C2: 汇率（特殊-CNY） | D2: 特殊币种 | E2: 金额 | F2: 类别 | G2: 描述 | H2: 分类
B3: A-12345 | E3: 169392.9 | F3: 招商银行 | H3: 基金
B4: A-12346 | E4: 10057.35 | F4: 中国银行 | H4: 活期
E5: 21072.81 | F5: 东方财富 | H5: 股票
C6: #VALUE! | D6: 0.01 | E6: {=ExpAug[[#This Row],[特殊币种]]*_FV(ExpAug[[#This Row],[汇率（特殊-CNY）]],"Price")} -> 0.009167 | F6: 中银香港 | H6: 活期
C7: 7.14 | D7: 1278.71 | E7: =ExpAug[[#This Row],[特殊币种]]*ExpAug[[#This Row],[汇率（特殊-CNY）]] -> 9129.9894 | F7: 币安Biance | H7: 比特币
E8: 14975.57 | F8: 长桥证券 | H8: 股票
E9: 81591.43 | F9: 东莞农村商业银行 | H9: 定期等安全投资
E10: =2.55+3.4 -> 5.95 | F10: 微信 | H10: 活期
E11: 1.96 | F11: 支付宝 | H11: 活期
A12: 汇总 | E12: =SUBTOTAL(109,ExpAug[金额]) -> 306227.97
A14: 日期 | B14: PO# | C14: 汇率（特殊-CNY） | D14: 特殊币种 | E14: 金额 | F14: 类别 | G14: 描述 | H14: 分类
E15: -59.03 | F15: 东方财富（A股） | G15: 填写收益 | H15: 东方财富（A股）
E16: 631.32 | F16: 长桥证券（美港股） | H16: 长桥证券（美港股）
C17: #VALUE! | D17: 0.01 | E17: {=ExpAug投资组合[[#This Row],[特殊币种]]*_FV(ExpAug投资组合[[#This Row],[汇率（特殊-CNY）]],"Price")} -> 0.071264 | F17: 比特币 | H17: 比特币
E18: 709.94 | F18: 基金（招行） | H18: 基金（招行）
A19: 汇总 | E19: =SUBTOTAL(109,ExpAug投资组合[金额]) -> 1282.3013

Sheet 9月
A1: 9月资产统计 | F1: 摘要 | G1: 提示
A2: 日期 | B2: PO# | C2: 汇率（特殊-CNY） | D2: 特殊币种 | E2: 金额 | F2: 类别 | G2: 描述 | H2: 分类
B3: A-12345 | E3: =21348.29 -> 21348.29 | F3: 招商银行
E4: 14351.12 | F4: 招商银行
E5: 104792.71 | F5: 招商银行
E6: 17668.31 | F6: 招商银行
E7: 14297.97 | F7: 招商银行
B8: A-12346 | E8: 294.56 | F8: 中国银行
E9: 20901.54 | F9: 东方财富
C10: #VALUE! | D10: 0.1 | E10: {=ExpSep[[#This Row],[特殊币种]]*_FV(ExpSep[[#This Row],[汇率（特殊-CNY）]],"Price")} -> 0.09167 | F10: 中银香港
C11: 6.97 | D11: 1285.92 | E11: =ExpSep[[#This Row],[特殊币种]]*ExpSep[[#This Row],[汇率（特殊-CNY）]] -> 8962.8624 | F11: 币安Biance
E12: 22866.26 | F12: 长桥证券
E13: 77615.66 | F13: 东莞农村商业银行
E14: =0.19+1.81 -> 2 | F14: 微信
E15: 0.96 | F15: 支付宝
A16: 汇总 | E16: =SUBTOTAL(109,ExpSep[金额]) -> 303102.33
A18: 日期 | B18: PO# | C18: 汇率（特殊-CNY） | D18: 特殊币种 | E18: 金额 | F18: 类别 | G18: 描述 | H18: 分类
E19: -167.04 | F19: 东方财富（A股） | G19: 填写收益 | H19: 东方财富（A股）
E20: 393.22 | F20: 长桥证券（美港股） | H20: 长桥证券（美港股）
C21: #VALUE! | D21: 0.01 | E21: {=ExpSep投资组合[[#This Row],[特殊币种]]*_FV(ExpSep投资组合[[#This Row],[汇率（特殊-CNY）]],"Price")} -> 0.071264 | F21: 比特币 | H21: 比特币
E22: 290.64 | F22: 基金（招行） | H22: 基金（招行）
A23: 汇总 | E23: =SUBTOTAL(109,ExpSep投资组合[金额]) -> 516.89126

Sheet 10月
A1: 10月资产统计 | F1: 摘要 | G1: 提示
A2: 日期 | B2: PO# | C2: 汇率（特殊-CNY） | D2: 特殊币种 | E2: 金额 | F2: 类别 | G2: 描述 | H2: 分类
B3: A-12345 | E3: 168232.73 | F3: 招商银行
B4: A-12346 | E4: 6.86 | F4: 中国银行
E5: 21785.1 | F5: 东方财富
C6: #VALUE! | D6: 0 | E6: {=ExpOct[[#This Row],[特殊币种]]*_FV(ExpOct[[#This Row],[汇率（特殊-CNY）]],"Price")} -> 0 | F6: 中银香港
C7: 6.77 | D7: 1298.54 | E7: =ExpOct[[#This Row],[特殊币种]]*ExpOct[[#This Row],[汇率（特殊-CNY）]] -> 8791.1158 | F7: 币安Biance
E8: 43401.35 | F8: 长桥证券
E9: 73876.46 | F9: 东莞农村商业银行 | G9: 切换成预算
E10: =6.29+154.64 -> 160.93 | F10: 微信
E11: 1.15 | F11: 支付宝
A12: 汇总 | E12: =SUBTOTAL(109,ExpOct[金额]) -> 316255.7
